Workbook
Name _GoBack: Variables!$M$11
Name Beliebig: Free1!$B:$XFD
Name Beliebig: Free2!$B:$XFD
Name Leeren: Variables!$A$3:$Y$54
Name R_id_var: Variables!$T$1
Name R_lab_before_var_sheet: Label!$F$1
Name R_miss_rec_lab: Variables!$R$1
Name R_miss_rec_val: Variables!$P$1
Name V_LabelvorVariablen: Label!$F$1
Name V_Lexikon: [1]!V_Lexikon
Name V_SysmisLab: Variables!$R$1
Name V_SysmisVal: Variables!$P$1
Name V_Variablen: Variables!$V:$X
Name V_VariablenEigenschaften: Variables!$A:$M
Name V_Verbatims_Code: Verbatims!$B$19:$R$19
Name V_Verbatims_Ergebnisdatei: Verbatims!$D$9
Name V_Verbatims_IDFormat: Verbatims!$D$6
Name V_Verbatims_IDVar: Verbatims!$D$5
Name V_Verbatims_InputDatei: Verbatims!$D$10
Name V_Verbatims_InputFrom: Verbatims!$D$12
Name V_Verbatims_InputTo: Verbatims!$D$13
Name V_VerbatimsDateiReplace: Verbatims!$D$7
Name V_VerbatimsDaten: Verbatims!$D$4
Name Vorlage: Label!#REF!
Name Vorlage: Variables!#REF!
Name Vorlage: Verbatims!$B$15:$R$15
Name Werte: Free1!$A$2:$A$43
Name Werte: Free2!$A$2:$A$275
Name Werte: Label!$A$3:$K$354
Name Werte: Variables!$K$3:$Y$54
Name Werte: Verbatims!$B$19:$R$19

Sheet Variables
A1: Variable Information | K1: Operation | L1: New var name | M1: New var label | N1: SYSMIS | O1: Value: | P1: -2 | Q1: Label: | R1: FILTER | S1: ID-Variable | T1: DC_ID
A2: Variable | B2: Position | C2: Label | D2: Measurement Level | E2: Role | F2: Column Width | G2: Alignment | H2: Print Format | I2: Write Format | J2: Missing Values | K2: a,d,n | Y2: 3
A3: id | B3: 1 | C3: <none> | D3: Nominal | E3: Input | F3: 12 | G3: Left | H3: A30 | I3: A30 | K3: n | S3: =S2&IF($L3<>"",$L3,$A3)&" " -> id | T3: =ISERROR(FIND(" "&UPPER(IF($L3<>"",$L3,$A3))&" ",#REF!)) -> TRUE | V3: =IF(W3<>W4,W3,"") -> id | W3: =LEFT(IF($L3<>"",$L3,$A3),Y3) -> id | X3: =IF(W2=W3,X2,"")&IF(AND(OR(LEFT(H3,1)="F",K3="a",K3="n"),RIGHT(A3,2)<>"00",RIGHT(A3,2)<>"98",RIGHT(A3,2)<>"99"),IF($L3<>"",$L3,$A3)&" ","") -> id | Y3: =Y2 -> 3
A4: screenout | B4: 2 | C4: <none> | D4: Nominal | E4: Input | F4: 7 | G4: Right | H4: F2 | I4: F2 | S4: =S3&IF($L4<>"",$L4,$A4)&" " -> id screenout | T4: =ISERROR(FIND(" "&UPPER(IF($L4<>"",$L4,$A4))&" ",#REF!)) -> TRUE | V4: =IF(W4<>W5,W4,"") -> scr | W4: =LEFT(IF($L4<>"",$L4,$A4),Y4) -> scr | X4: =IF(W3=W4,X3,"")&IF(AND(OR(LEFT(H4,1)="F",K4="a",K4="n"),RIGHT(A4,2)<>"00",RIGHT(A4,2)<>"98",RIGHT(A4,2)<>"99"),IF($L4<>"",$L4,$A4)&" ","") -> screenout | Y4: =Y3 -> 3
A5: datum | B5: 3 | D5: Scale | E5: Input | F5: 13 | G5: Right | H5: DATE11 | I5: DATE11 | S5: =S4&IF($L5<>"",$L5,$A5)&" " -> id screenout datum | T5: =ISERROR(FIND(" "&UPPER(IF($L5<>"",$L5,$A5))&" ",#REF!)) -> TRUE | V5: =IF(W5<>W6,W5,"") -> dat | W5: =LEFT(IF($L5<>"",$L5,$A5),Y5) -> dat | X5: =IF(W4=W5,X4,"")&IF(AND(OR(LEFT(H5,1)="F",K5="a",K5="n"),RIGHT(A5,2)<>"00",RIGHT(A5,2)<>"98",RIGHT(A5,2)<>"99"),IF($L5<>"",$L5,$A5)&" ","") | Y5: =Y4 -> 3
A6: q1 | B6: 14 | D6: Nominal | E6: Input | F6: 7 | G6: Right | H6: F2 | I6: F2 | M6: 1. Wie viele Mitarbeiter beschäftigt Ihr Unternehmen? | S6: =S5&IF($L6<>"",$L6,$A6)&" " -> id screenout datum q1 | T6: =ISERROR(FIND(" "&UPPER(IF($L6<>"",$L6,$A6))&" ",#REF!)) -> TRUE | V6: =IF(W6<>W7,W6,"") -> q1 | W6: =LEFT(IF($L6<>"",$L6,$A6),Y6) -> q1 | X6: =IF(W5=W6,X5,"")&IF(AND(OR(LEFT(H6,1)="F",K6="a",K6="n"),RIGHT(A6,2)<>"00",RIGHT(A6,2)<>"98",RIGHT(A6,2)<>"99"),IF($L6<>"",$L6,$A6)&" ","") -> q1 | Y6: =Y5 -> 3
A7: q2_00 | B7: 15 | D7: Nominal | E7: Input | F7: 7 | G7: Right | H7: F2 | I7: F2 | M7: 2. Welche Art von Studien führen Sie mit dem Tabellenbandtool durch? | S7: =S6&IF($L7<>"",$L7,$A7)&" " -> id screenout datum q1 q2_00 | T7: =ISERROR(FIND(" "&UPPER(IF($L7<>"",$L7,$A7))&" ",#REF!)) -> TRUE | V7: =IF(W7<>W8,W7,"") | W7: =LEFT(IF($L7<>"",$L7,$A7),Y7) -> q2_ | X7: =IF(W6=W7,X6,"")&IF(AND(OR(LEFT(H7,1)="F",K7="a",K7="n"),RIGHT(A7,2)<>"00",RIGHT(A7,2)<>"98",RIGHT(A7,2)<>"99"),IF($L7<>"",$L7,$A7)&" ","") | Y7: =Y6 -> 3
A8: q2_01 | B8: 16 | D8: Nominal | E8: Input | F8: 7 | G8: Right | H8: F2 | I8: F2 | S8: =S7&IF($L8<>"",$L8,$A8)&" " -> id screenout datum q1 q2_00 q2_01 | T8: =ISERROR(FIND(" "&UPPER(IF($L8<>"",$L8,$A8))&" ",#REF!)) -> TRUE | V8: =IF(W8<>W9,W8,"") | W8: =LEFT(IF($L8<>"",$L8,$A8),Y8) -> q2_ | X8: =IF(W7=W8,X7,"")&IF(AND(OR(LEFT(H8,1)="F",K8="a",K8="n"),RIGHT(A8,2)<>"00",RIGHT(A8,2)<>"98",RIGHT(A8,2)<>"99"),IF($L8<>"",$L8,$A8)&" ","") -> q2_01 | Y8: =Y7 -> 3
A9: q2_02 | B9: 17 | D9: Nominal | E9: Input | F9: 7 | G9: Right | H9: F2 | I9: F2 | M9: Kundenzufriedenheit | S9: =S8&IF($L9<>"",$L9,$A9)&" " -> id screenout datum q1 q2_00 q2_01 q2_02 | T9: =ISERROR(FIND(" "&UPPER(IF($L9<>"",$L9,$A9))&" ",#REF!)) -> TRUE | V9: =IF(W9<>W10,W9,"") | W9: =LEFT(IF($L9<>"",$L9,$A9),Y9) -> q2_ | X9: =IF(W8=W9,X8,"")&IF(AND(OR(LEFT(H9,1)="F",K9="a",K9="n"),RIGHT(A9,2)<>"00",RIGHT(A9,2)<>"98",RIGHT(A9,2)<>"99"),IF($L9<>"",$L9,$A9)&" ","") -> q2_01 q2_02 | Y9: =Y8 -> 3
A10: q2_03 | B10: 18 | D10: Nominal | E10: Input | F10: 7 | G10: Right | H10: F2 | I10: F2 | M10: Marktvolumen | S10: =S9&IF($L10<>"",$L10,$A10)&" " -> id screenout datum q1 q2_00 q2_01 q2_02 q2_03 | T10: =ISERROR(FIND(" "&UPPER(IF($L10<>"",$L10,$A10))&" ",#REF!)) -> TRUE | V10: =IF(W10<>W11,W10,"") | W10: =LEFT(IF($L10<>"",$L10,$A10),Y10) -> q2_ | X10: =IF(W9=W10,X9,"")&IF(AND(OR(LEFT(H10,1)="F",K10="a",K10="n"),RIGHT(A10,2)<>"00",RIGHT(A10,2)<>"98",RIGHT(A10,2)<>"99"),IF($L10<>"",$L10,$A10)&" ","") -> q2_01 q2_02 q2_03 | Y10: =Y9 -> 3
A11: q2_04 | B11: 19 | D11: Nominal | E11: Input | F11: 7 | G11: Right | H11: F2 | I11: F2 | M11: Onlineauftritte | S11: =S10&IF($L11<>"",$L11,$A11)&" " -> id screenout datum q1 q2_00 q2_01 q2_02 q2_03 q2_04 | T11: =ISERROR(FIND(" "&UPPER(IF($L11<>"",$L11,$A11))&" ",#REF!)) -> TRUE | V11: =IF(W11<>W12,W11,"") | W11: =LEFT(IF($L11<>"",$L11,$A11),Y11) -> q2_ | X11: =IF(W10=W11,X10,"")&IF(AND(OR(LEFT(H11,1)="F",K11="a",K11="n"),RIGHT(A11,2)<>"00",RIGHT(A11,2)<>"98",RIGHT(A11,2)<>"99"),IF($L11<>"",$L11,$A11)&" ","") -> q2_01 q2_02 q2_03 q2_04 | Y11: =Y10 -> 3
A12: q2_05 | B12: 20 | D12: Nominal | E12: Input | F12: 7 | G12: Right | H12: F2 | I12: F2 | M12: Branchenbarometer | S12: =S11&IF($L12<>"",$L12,$A12)&" " -> id screenout datum q1 q2_00 q2_01 q2_02 q2_03 q2_04 q2_05 | T12: =ISERROR(FIND(" "&UPPER(IF($L12<>"",$L12,$A12))&" ",#REF!)) -> TRUE | V12: =IF(W12<>W13,W12,"") | W12: =LEFT(IF($L12<>"",$L12,$A12),Y12) -> q2_ | X12: =IF(W11=W12,X11,"")&IF(AND(OR(LEFT(H12,1)="F",K12="a",K12="n"),RIGHT(A12,2)<>"00",RIGHT(A12,2)<>"98",RIGHT(A12,2)<>"99"),IF($L12<>"",$L12,$A12)&" ","") -> q2_01 q2_02 q2_03 q2_04 q2_05 | Y12: =Y11 -> 3
A13: q2_06 | B13: 21 | D13: Nominal | E13: Input | F13: 7 | G13: Right | H13: F2 | I13: F2 | M13: Strukturanalyse | S13: =S12&IF($L13<>"",$L13,$A13)&" " -> id screenout datum q1 q2_00 q2_01 q2_02 q2_03 q2_04 q2_05 q2_06 | T13: =ISERROR(FIND(" "&UPPER(IF($L13<>"",$L13,$A13))&" ",#REF!)) -> TRUE | V13: =IF(W13<>W14,W13,"") | W13: =LEFT(IF($L13<>"",$L13,$A13),Y13) -> q2_ | X13: =IF(W12=W13,X12,"")&IF(AND(OR(LEFT(H13,1)="F",K13="a",K13="n"),RIGHT(A13,2)<>"00",RIGHT(A13,2)<>"98",RIGHT(A13,2)<>"99"),IF($L13<>"",$L13,$A13)&" ","") -> q2_01 q2_02 q2_03 q2_04 q2_05 q2_06 | Y13: =Y12 -> 3
A14: q2_07 | B14: 22 | D14: Nominal | E14: Input | F14: 7 | G14: Right | H14: F2 | I14: F2 | M14: Werbewirkungsmessung | S14: =S13&IF($L14<>"",$L14,$A14)&" " -> id screenout datum q1 q2_00 q2_01 q2_02 q2_03 q2_04 q2_05 q2_06 q2_07 | T14: =ISERROR(FIND(" "&UPPER(IF($L14<>"",$L14,$A14))&" ",#REF!)) -> TRUE | V14: =IF(W14<>W15,W14,"") | W14: =LEFT(IF($L14<>"",$L14,$A14),Y14) -> q2_ | X14: =IF(W13=W14,X13,"")&IF(AND(OR(LEFT(H14,1)="F",K14="a",K14="n"),RIGHT(A14,2)<>"00",RIGHT(A14,2)<>"98",RIGHT(A14,2)<>"99"),IF($L14<>"",$L14,$A14)&" ","") -> q2_01 q2_02 q2_03 q2_04 q2_05 q2_06 q2_07 | Y14: =Y13 -> 3
A15: q2_99 | B15: 23 | D15: Nominal | E15: Input | F15: 7 | G15: Right | H15: F2 | I15: F2 | M15: Sonstige | S15: =S14&IF($L15<>"",$L15,$A15)&" " -> id screenout datum q1 q2_00 q2_01 q2_02 q2_03 q2_04 q2_05 q2_06 q2_07 q2_99 | T15: =ISERROR(FIND(" "&UPPER(IF($L15<>"",$L15,$A15))&" ",#REF!)) -> TRUE | V15: =IF(W15<>W16,W15,"") -> q2_ | W15: =LEFT(IF($L15<>"",$L15,$A15),Y15) -> q2_ | X15: =IF(W14=W15,X14,"")&IF(AND(OR(LEFT(H15,1)="F",K15="a",K15="n"),RIGHT(A15,2)<>"00",RIGHT(A15,2)<>"98",RIGHT(A15,2)<>"99"),IF($L15<>"",$L15,$A15)&" ","") -> q2_01 q2_02 q2_03 q2_04 q2_05 q2_06 q2_07 | Y15: =Y14 -> 3
A16: q3a | B16: 24 | D16: Scale | E16: Input | F16: 5 | G16: Right | H16: F3 | I16: F3 | M16: Kundenzufriedenheit | S16: =S15&IF($L16<>"",$L16,$A16)&" " -> id screenout datum q1 q2_00 q2_01 q2_02 q2_03 q2_04 q2_05 q2_06 q2_07 q2_99 q3a | T16: =ISERROR(FIND(" "&UPPER(IF($L16<>"",$L16,$A16))&" ",#REF!)) -> TRUE | V16: =IF(W16<>W17,W16,"") -> q3a | W16: =LEFT(IF($L16<>"",$L16,$A16),Y16) -> q3a | X16: =IF(W15=W16,X15,"")&IF(AND(OR(LEFT(H16,1)="F",K16="a",K16="n"),RIGHT(A16,2)<>"00",RIGHT(A16,2)<>"98",RIGHT(A16,2)<>"99"),IF($L16<>"",$L16,$A16)&" ","") -> q3a | Y16: =Y15 -> 3
A17: q3b | B17: 25 | D17: Scale | E17: Input | F17: 5 | G17: Right | H17: F3 | I17: F3 | M17: Marktvolumen | S17: =S16&IF($L17<>"",$L17,$A17)&" " -> id screenout datum q1 q2_00 q2_01 q2_02 q2_03 q2_04 q2_05 q2_06 q2_07 q2_99 q3a q3b | T17: =ISERROR(FIND(" "&UPPER(IF($L17<>"",$L17,$A17))&" ",#REF!)) -> TRUE | V17: =IF(W17<>W18,W17,"") -> q3b | W17: =LEFT(IF($L17<>"",$L17,$A17),Y17) -> q3b | X17: =IF(W16=W17,X16,"")&IF(AND(OR(LEFT(H17,1)="F",K17="a",K17="n"),RIGHT(A17,2)<>"00",RIGHT(A17,2)<>"98",RIGHT(A17,2)<>"99"),IF($L17<>"",$L17,$A17)&" ","") -> q3b | Y17: =Y16 -> 3
A18: q3c | B18: 26 | D18: Scale | E18: Input | F18: 5 | G18: Right | H18: F3 | I18: F3 | M18: Onlineauftritte | S18: =S17&IF($L18<>"",$L18,$A18)&" " -> id screenout datum q1 q2_00 q2_01 q2_02 q2_03 q2_04 q2_05 q2_06 q2_07 q2_99 q3a q3b q3c | T18: =ISERROR(FIND(" "&UPPER(IF($L18<>"",$L18,$A18))&" ",#REF!)) -> TRUE | V18: =IF(W18<>W19,W18,"") -> q3c | W18: =LEFT(IF($L18<>"",$L18,$A18),Y18) -> q3c | X18: =IF(W17=W18,X17,"")&IF(AND(OR(LEFT(H18,1)="F",K18="a",K18="n"),RIGHT(A18,2)<>"00",RIGHT(A18,2)<>"98",RIGHT(A18,2)<>"99"),IF($L18<>"",$L18,$A18)&" ","") -> q3c | Y18: =Y17 -> 3
A19: q3d | B19: 27 | D19: Scale | E19: Input | F19: 5 | G19: Right | H19: F3 | I19: F3 | M19: Branchenbarometer | S19: =S18&IF($L19<>"",$L19,$A19)&" " -> id screenout datum q1 q2_00 q2_01 q2_02 q2_03 q2_04 q2_05 q2_06 q2_07 q2_99 q3a q3b q3c q3d | T19: =ISERROR(FIND(" "&UPPER(IF($L19<>"",$L19,$A19))&" ",#REF!)) -> TRUE | V19: =IF(W19<>W20,W19,"") -> q3d | W19: =LEFT(IF($L19<>"",$L19,$A19),Y19) -> q3d | X19: =IF(W18=W19,X18,"")&IF(AND(OR(LEFT(H19,1)="F",K19="a",K19="n"),RIGHT(A19,2)<>"00",RIGHT(A19,2)<>"98",RIGHT(A19,2)<>"99"),IF($L19<>"",$L19,$A19)&" ","") -> q3d | Y19: =Y18 -> 3
A20: q3e | B20: 28 | D20: Scale | E20: Input | F20: 5 | G20: Right | H20: F3 | I20: F3 | M20: Strukturanalyse | S20: =S19&IF($L20<>"",$L20,$A20)&" " -> id screenout datum q1 q2_00 q2_01 q2_02 q2_03 q2_04 q2_05 q2_06 q2_07 q2_99 q3a q3b q3c q3d q3e | T20: =ISERROR(FIND(" "&UPPER(IF($L20<>"",$L20,$A20))&" ",#REF!)) -> TRUE | V20: =IF(W20<>W21,W20,"") -> q3e | W20: =LEFT(IF($L20<>"",$L20,$A20),Y20) -> q3e | X20: =IF(W19=W20,X19,"")&IF(AND(OR(LEFT(H20,1)="F",K20="a",K20="n"),RIGHT(A20,2)<>"00",RIGHT(A20,2)<>"98",RIGHT(A20,2)<>"99"),IF($L20<>"",$L20,$A20)&" ","") -> q3e | Y20: =Y19 -> 3
... A32: sel1 | B32: 67 | D32: Scale | E32: Input | F32: 6 | G32: Right | H32: F3 | I32: F3 | M32: Abgefragte Studienarten | S32: =S31&IF($L32<>"",$L32,$A32)&" " -> id screenout datum q1 q2_00 q2_01 q2_02 q2_03 q2_04 q2_05 q2_06 q2_07 q2_99 q3a q3b q3c q3d q3e q3f q3g q4 q6a q6b q6c q6d q6e q6f q6g q6h sel1 | T32: =ISERROR(FIND(" "&UPPER(IF($L32<>"",$L32,$A32))&" ",#REF!)) -> TRUE | V32: =IF(W32<>W33,W32,"") -> sel | W32: =LEFT(IF($L32<>"",$L32,$A32),Y32) -> sel | X32: =IF(W31=W32,X31,"")&IF(AND(OR(LEFT(H32,1)="F",K32="a",K32="n"),RIGHT(A32,2)<>"00",RIGHT(A32,2)<>"98",RIGHT(A32,2)<>"99"),IF($L32<>"",$L32,$A32)&" ","") -> sel1 | Y32: =Y31 -> 3
A33: q7a1 | B33: 68 | D33: Scale | E33: Input | F33: 6 | G33: Right | H33: F3 | I33: F3 | M33: =INDEX($M$24:$M$31,P33) -> Schnelle Umsetzung | P33: 1 | S33: =S32&IF($L33<>"",$L33,$A33)&" " -> id screenout datum q1 q2_00 q2_01 q2_02 q2_03 q2_04 q2_05 q2_06 q2_07 q2_99 q3a q3b q3c q3d q3e q3f q3g q4 q6a q6b q6c q6d q6e q6f q6g q6h sel1 q7a1 | T33: =ISERROR(FIND(" "&UPPER(IF($L33<>"",$L33,$A33))&" ",#REF!)) -> TRUE | V33: =IF(W33<>W34,W33,"") | W33: =LEFT(IF($L33<>"",$L33,$A33),Y33) -> q7a | X33: =IF(W32=W33,X32,"")&IF(AND(OR(LEFT(H33,1)="F",K33="a",K33="n"),RIGHT(A33,2)<>"00",RIGHT(A33,2)<>"98",RIGHT(A33,2)<>"99"),IF($L33<>"",$L33,$A33)&" ","") -> q7a1 | Y33: =Y32 -> 3
A34: q7a2 | B34: 69 | D34: Scale | E34: Input | F34: 7 | G34: Right | H34: F3 | I34: F3 | M34: =INDEX($M$24:$M$31,P34) -> Schnelle Umsetzung | P34: =P33 -> 1 | S34: =S33&IF($L34<>"",$L34,$A34)&" " -> id screenout datum q1 q2_00 q2_01 q2_02 q2_03 q2_04 q2_05 q2_06 q2_07 q2_99 q3a q3b q3c q3d q3e q3f q3g q4 q6a q6b q6c q6d q6e q6f q6g q6h sel1 q7a1 q7a2 | T34: =ISERROR(FIND(" "&UPPER(IF($L34<>"",$L34,$A34))&" ",#REF!)) -> TRUE | V34: =IF(W34<>W35,W34,"") -> q7a | W34: =LEFT(IF($L34<>"",$L34,$A34),Y34) -> q7a | X34: =IF(W33=W34,X33,"")&IF(AND(OR(LEFT(H34,1)="F",K34="a",K34="n"),RIGHT(A34,2)<>"00",RIGHT(A34,2)<>"98",RIGHT(A34,2)<>"99"),IF($L34<>"",$L34,$A34)&" ","") -> q7a1 q7a2 | Y34: =Y33 -> 3
A35: q7b1 | B35: 70 | D35: Scale | E35: Input | F35: 6 | G35: Right | H35: F3 | I35: F3 | M35: =INDEX($M$24:$M$31,P35) -> Kurzfristige Anpassungen | P35: =P34+1 -> 2 | S35: =S34&IF($L35<>"",$L35,$A35)&" " -> id screenout datum q1 q2_00 q2_01 q2_02 q2_03 q2_04 q2_05 q2_06 q2_07 q2_99 q3a q3b q3c q3d q3e q3f q3g q4 q6a q6b q6c q6d q6e q6f q6g q6h sel1 q7a1 q7a2 q7b1 | T35: =ISERROR(FIND(" "&UPPER(IF($L35<>"",$L35,$A35))&" ",#REF!)) -> TRUE | V35: =IF(W35<>W36,W35,"") | W35: =LEFT(IF($L35<>"",$L35,$A35),Y35) -> q7b | X35: =IF(W34=W35,X34,"")&IF(AND(OR(LEFT(H35,1)="F",K35="a",K35="n"),RIGHT(A35,2)<>"00",RIGHT(A35,2)<>"98",RIGHT(A35,2)<>"99"),IF($L35<>"",$L35,$A35)&" ","") -> q7b1 | Y35: =Y34 -> 3
A36: q7b2 | B36: 71 | D36: Scale | E36: Input | F36: 7 | G36: Right | H36: F3 | I36: F3 | M36: =INDEX($M$24:$M$31,P36) -> Kurzfristige Anpassungen | P36: =P35 -> 2 | S36: =S35&IF($L36<>"",$L36,$A36)&" " -> id screenout datum q1 q2_00 q2_01 q2_02 q2_03 q2_04 q2_05 q2_06 q2_07 q2_99 q3a q3b q3c q3d q3e q3f q3g q4 q6a q6b q6c q6d q6e q6f q6g q6h sel1 q7a1 q7a2 q7b1 q7b2 | T36: =ISERROR(FIND(" "&UPPER(IF($L36<>"",$L36,$A36))&" ",#REF!)) -> TRUE | V36: =IF(W36<>W37,W36,"") -> q7b | W36: =LEFT(IF($L36<>"",$L36,$A36),Y36) -> q7b | X36: =IF(W35=W36,X35,"")&IF(AND(OR(LEFT(H36,1)="F",K36="a",K36="n"),RIGHT(A36,2)<>"00",RIGHT(A36,2)<>"98",RIGHT(A36,2)<>"99"),IF($L36<>"",$L36,$A36)&" ","") -> q7b1 q7b2 | Y36: =Y35 -> 3
A37: q7c1 | B37: 72 | D37: Scale | E37: Input | F37: 6 | G37: Right | H37: F3 | I37: F3 | M37: =INDEX($M$24:$M$31,P37) -> Korrektheit der Daten | P37: =P36+1 -> 3 | S37: =S36&IF($L37<>"",$L37,$A37)&" " -> id screenout datum q1 q2_00 q2_01 q2_02 q2_03 q2_04 q2_05 q2_06 q2_07 q2_99 q3a q3b q3c q3d q3e q3f q3g q4 q6a q6b q6c q6d q6e q6f q6g q6h sel1 q7a1 q7a2 q7b1 q7b2 q7c1 | T37: =ISERROR(FIND(" "&UPPER(IF($L37<>"",$L37,$A37))&" ",#REF!)) -> TRUE | V37: =IF(W37<>W38,W37,"") | W37: =LEFT(IF($L37<>"",$L37,$A37),Y37) -> q7c | X37: =IF(W36=W37,X36,"")&IF(AND(OR(LEFT(H37,1)="F",K37="a",K37="n"),RIGHT(A37,2)<>"00",RIGHT(A37,2)<>"98",RIGHT(A37,2)<>"99"),IF($L37<>"",$L37,$A37)&" ","") -> q7c1 | Y37: =Y36 -> 3
A38: q7c2 | B38: 73 | D38: Scale | E38: Input | F38: 7 | G38: Right | H38: F3 | I38: F3 | M38: =INDEX($M$24:$M$31,P38) -> Korrektheit der Daten | P38: =P37 -> 3 | S38: =S37&IF($L38<>"",$L38,$A38)&" " -> id screenout datum q1 q2_00 q2_01 q2_02 q2_03 q2_04 q2_05 q2_06 q2_07 q2_99 q3a q3b q3c q3d q3e q3f q3g q4 q6a q6b q6c q6d q6e q6f q6g q6h sel1 q7a1 q7a2 q7b1 q7b2 q7c1 q7c2 | T38: =ISERROR(FIND(" "&UPPER(IF($L38<>"",$L38,$A38))&" ",#REF!)) -> TRUE | V38: =IF(W38<>W39,W38,"") -> q7c | W38: =LEFT(IF($L38<>"",$L38,$A38),Y38) -> q7c | X38: =IF(W37=W38,X37,"")&IF(AND(OR(LEFT(H38,1)="F",K38="a",K38="n"),RIGHT(A38,2)<>"00",RIGHT(A38,2)<>"98",RIGHT(A38,2)<>"99"),IF($L38<>"",$L38,$A38)&" ","") -> q7c1 q7c2 | Y38: =Y37 -> 3
A39: q7d1 | B39: 74 | D39: Scale | E39: Input | F39: 6 | G39: Right | H39: F3 | I39: F3 | M39: =INDEX($M$24:$M$31,P39) -> Freundlichkeit der Tabellenbandersteller | P39: =P38+1 -> 4 | S39: =S38&IF($L39<>"",$L39,$A39)&" " -> id screenout datum q1 q2_00 q2_01 q2_02 q2_03 q2_04 q2_05 q2_06 q2_07 q2_99 q3a q3b q3c q3d q3e q3f q3g q4 q6a q6b q6c q6d q6e q6f q6g q6h sel1 q7a1 q7a2 q7b1 q7b2 q7c1 q7c2 q7d1 | T39: =ISERROR(FIND(" "&UPPER(IF($L39<>"",$L39,$A39))&" ",#REF!)) -> TRUE | V39: =IF(W39<>W40,W39,"") | W39: =LEFT(IF($L39<>"",$L39,$A39),Y39) -> q7d | X39: =IF(W38=W39,X38,"")&IF(AND(OR(LEFT(H39,1)="F",K39="a",K39="n"),RIGHT(A39,2)<>"00",RIGHT(A39,2)<>"98",RIGHT(A39,2)<>"99"),IF($L39<>"",$L39,$A39)&" ","") -> q7d1 | Y39: =Y38 -> 3
A40: q7d2 | B40: 75 | D40: Scale | E40: Input | F40: 7 | G40: Right | H40: F3 | I40: F3 | M40: =INDEX($M$24:$M$31,P40) -> Freundlichkeit der Tabellenbandersteller | P40: =P39 -> 4 | S40: =S39&IF($L40<>"",$L40,$A40)&" " -> id screenout datum q1 q2_00 q2_01 q2_02 q2_03 q2_04 q2_05 q2_06 q2_07 q2_99 q3a q3b q3c q3d q3e q3f q3g q4 q6a q6b q6c q6d q6e q6f q6g q6h sel1 q7a1 q7a2 q7b1 q7b2 q7c1 q7c2 q7d1 q7d2 | T40: =ISERROR(FIND(" "&UPPER(IF($L40<>"",$L40,$A40))&" ",#REF!)) -> TRUE | V40: =IF(W40<>W41,W40,"") -> q7d | W40: =LEFT(IF($L40<>"",$L40,$A40),Y40) -> q7d | X40: =IF(W39=W40,X39,"")&IF(AND(OR(LEFT(H40,1)="F",K40="a",K40="n"),RIGHT(A40,2)<>"00",RIGHT(A40,2)<>"98",RIGHT(A40,2)<>"99"),IF($L40<>"",$L40,$A40)&" ","") -> q7d1 q7d2 | Y40: =Y39 -> 3
A41: q7e1 | B41: 76 | D41: Scale | E41: Input | F41: 6 | G41: Right | H41: F3 | I41: F3 | M41: =INDEX($M$24:$M$31,P41) -> Langfristige Zusammenarbeit | P41: =P40+1 -> 5 | S41: =S40&IF($L41<>"",$L41,$A41)&" " -> id screenout datum q1 q2_00 q2_01 q2_02 q2_03 q2_04 q2_05 q2_06 q2_07 q2_99 q3a q3b q3c q3d q3e q3f q3g q4 q6a q6b q6c q6d q6e q6f q6g q6h sel1 q7a1 q7a2 q7b1 q7b2 q7c1 q7c2 q7d1 q7d2 q7e1 | T41: =ISERROR(FIND(" "&UPPER(IF($L41<>"",$L41,$A41))&" ",#REF!)) -> TRUE | V41: =IF(W41<>W42,W41,"") | W41: =LEFT(IF($L41<>"",$L41,$A41),Y41) -> q7e | X41: =IF(W40=W41,X40,"")&IF(AND(OR(LEFT(H41,1)="F",K41="a",K41="n"),RIGHT(A41,2)<>"00",RIGHT(A41,2)<>"98",RIGHT(A41,2)<>"99"),IF($L41<>"",$L41,$A41)&" ","") -> q7e1 | Y41: =Y40 -> 3
A42: q7e2 | B42: 77 | D42: Scale | E42: Input | F42: 7 | G42: Right | H42: F3 | I42: F3 | M42: =INDEX($M$24:$M$31,P42) -> Langfristige Zusammenarbeit | P42: =P41 -> 5 | S42: =S41&IF($L42<>"",$L42,$A42)&" " -> id screenout datum q1 q2_00 q2_01 q2_02 q2_03 q2_04 q2_05 q2_06 q2_07 q2_99 q3a q3b q3c q3d q3e q3f q3g q4 q6a q6b q6c q6d q6e q6f q6g q6h sel1 q7a1 q7a2 q7b1 q7b2 q7c1 q7c2 q7d1 q7d2 q7e1 q7e2 | T42: =ISERROR(FIND(" "&UPPER(IF($L42<>"",$L42,$A42))&" ",#REF!)) -> TRUE | V42: =IF(W42<>W43,W42,"") -> q7e | W42: =LEFT(IF($L42<>"",$L42,$A42),Y42) -> q7e | X42: =IF(W41=W42,X41,"")&IF(AND(OR(LEFT(H42,1)="F",K42="a",K42="n"),RIGHT(A42,2)<>"00",RIGHT(A42,2)<>"98",RIGHT(A42,2)<>"99"),IF($L42<>"",$L42,$A42)&" ","") -> q7e1 q7e2 | Y42: =Y41 -> 3
A43: q7f1 | B43: 78 | D43: Scale | E43: Input | F43: 6 | G43: Right | H43: F3 | I43: F3 | L43: q7h1 | M43: =INDEX($M$24:$M$31,P43) -> Gute telefonische Erreichbarkeit | P43: =P42+1 -> 6 | S43: =S42&IF($L43<>"",$L43,$A43)&" " -> id screenout datum q1 q2_00 q2_01 q2_02 q2_03 q2_04 q2_05 q2_06 q2_07 q2_99 q3a q3b q3c q3d q3e q3f q3g q4 q6a q6b q6c q6d q6e q6f q6g q6h sel1 q7a1 q7a2 q7b1 q7b2 q7c1 q7c2 q7d1 q7d2 q7e1 q7e2 q7h1 | T43: =ISERROR(FIND(" "&UPPER(IF($L43<>"",$L43,$A43))&" ",#REF!)) -> TRUE | V43: =IF(W43<>W44,W43,"") | W43: =LEFT(IF($L43<>"",$L43,$A43),Y43) -> q7h | X43: =IF(W42=W43,X42,"")&IF(AND(OR(LEFT(H43,1)="F",K43="a",K43="n"),RIGHT(A43,2)<>"00",RIGHT(A43,2)<>"98",RIGHT(A43,2)<>"99"),IF($L43<>"",$L43,$A43)&" ","") -> q7h1 | Y43: =Y42 -> 3
A44: q7f2 | B44: 79 | D44: Scale | E44: Input | F44: 7 | G44: Right | H44: F3 | I44: F3 | L44: q7h2 | M44: =INDEX($M$24:$M$31,P44) -> Gute telefonische Erreichbarkeit | P44: =P43 -> 6 | S44: =S43&IF($L44<>"",$L44,$A44)&" " -> id screenout datum q1 q2_00 q2_01 q2_02 q2_03 q2_04 q2_05 q2_06 q2_07 q2_99 q3a q3b q3c q3d q3e q3f q3g q4 q6a q6b q6c q6d q6e q6f q6g q6h sel1 q7a1 q7a2 q7b1 q7b2 q7c1 q7c2 q7d1 q7d2 q7e1 q7e2 q7h1 q7h2 | T44: =ISERROR(FIND(" "&UPPER(IF($L44<>"",$L44,$A44))&" ",#REF!)) -> TRUE | V44: =IF(W44<>W45,W44,"") -> q7h | W44: =LEFT(IF($L44<>"",$L44,$A44),Y44) -> q7h | X44: =IF(W43=W44,X43,"")&IF(AND(OR(LEFT(H44,1)="F",K44="a",K44="n"),RIGHT(A44,2)<>"00",RIGHT(A44,2)<>"98",RIGHT(A44,2)<>"99"),IF($L44<>"",$L44,$A44)&" ","") -> q7h1 q7h2 | Y44: =Y43 -> 3
A45: q7g1 | B45: 80 | D45: Scale | E45: Input | F45: 6 | G45: Right | H45: F3 | I45: F3 | L45: q7f1 | M45: =INDEX($M$24:$M$31,P45) -> Wochenenderreichbarkeit | P45: =P44+1 -> 7 | S45: =S44&IF($L45<>"",$L45,$A45)&" " -> id screenout datum q1 q2_00 q2_01 q2_02 q2_03 q2_04 q2_05 q2_06 q2_07 q2_99 q3a q3b q3c q3d q3e q3f q3g q4 q6a q6b q6c q6d q6e q6f q6g q6h sel1 q7a1 q7a2 q7b1 q7b2 q7c1 q7c2 q7d1 q7d2 q7e1 q7e2 q7h1 q7h2 q7f1 | T45: =ISERROR(FIND(" "&UPPER(IF($L45<>"",$L45,$A45))&" ",#REF!)) -> TRUE | V45: =IF(W45<>W46,W45,"") | W45: =LEFT(IF($L45<>"",$L45,$A45),Y45) -> q7f | X45: =IF(W44=W45,X44,"")&IF(AND(OR(LEFT(H45,1)="F",K45="a",K45="n"),RIGHT(A45,2)<>"00",RIGHT(A45,2)<>"98",RIGHT(A45,2)<>"99"),IF($L45<>"",$L45,$A45)&" ","") -> q7f1 | Y45: =Y44 -> 3
A46: q7g2 | B46: 81 | D46: Scale | E46: Input | F46: 7 | G46: Right | H46: F3 | I46: F3 | L46: q7f2 | M46: =INDEX($M$24:$M$31,P46) -> Wochenenderreichbarkeit | P46: =P45 -> 7 | S46: =S45&IF($L46<>"",$L46,$A46)&" " -> id screenout datum q1 q2_00 q2_01 q2_02 q2_03 q2_04 q2_05 q2_06 q2_07 q2_99 q3a q3b q3c q3d q3e q3f q3g q4 q6a q6b q6c q6d q6e q6f q6g q6h sel1 q7a1 q7a2 q7b1 q7b2 q7c1 q7c2 q7d1 q7d2 q7e1 q7e2 q7h1 q7h2 q7f1 q7f2 | T46: =ISERROR(FIND(" "&UPPER(IF($L46<>"",$L46,$A46))&" ",#REF!)) -> TRUE | V46: =IF(W46<>W47,W46,"") -> q7f | W46: =LEFT(IF($L46<>"",$L46,$A46),Y46) -> q7f | X46: =IF(W45=W46,X45,"")&IF(AND(OR(LEFT(H46,1)="F",K46="a",K46="n"),RIGHT(A46,2)<>"00",RIGHT(A46,2)<>"98",RIGHT(A46,2)<>"99"),IF($L46<>"",$L46,$A46)&" ","") -> q7f1 q7f2 | Y46: =Y45 -> 3
A47: q7h1 | B47: 82 | D47: Scale | E47: Input | F47: 6 | G47: Right | H47: F3 | I47: F3 | L47: q7g1 | M47: =INDEX($M$24:$M$31,P47) -> Einhaltung von Zusagen | P47: =P46+1 -> 8 | S47: =S46&IF($L47<>"",$L47,$A47)&" " -> id screenout datum q1 q2_00 q2_01 q2_02 q2_03 q2_04 q2_05 q2_06 q2_07 q2_99 q3a q3b q3c q3d q3e q3f q3g q4 q6a q6b q6c q6d q6e q6f q6g q6h sel1 q7a1 q7a2 q7b1 q7b2 q7c1 q7c2 q7d1 q7d2 q7e1 q7e2 q7h1 q7h2 q7f1 q7f2 q7g1 | T47: =ISERROR(FIND(" "&UPPER(IF($L47<>"",$L47,$A47))&" ",#REF!)) -> TRUE | V47: =IF(W47<>W48,W47,"") | W47: =LEFT(IF($L47<>"",$L47,$A47),Y47) -> q7g | X47: =IF(W46=W47,X46,"")&IF(AND(OR(LEFT(H47,1)="F",K47="a",K47="n"),RIGHT(A47,2)<>"00",RIGHT(A47,2)<>"98",RIGHT(A47,2)<>"99"),IF($L47<>"",$L47,$A47)&" ","") -> q7g1 | Y47: =Y46 -> 3
A48: q7h2 | B48: 83 | D48: Scale | E48: Input | F48: 7 | G48: Right | H48: F3 | I48: F3 | L48: q7g2 | M48: =INDEX($M$24:$M$31,P48) -> Einhaltung von Zusagen | P48: =P47 -> 8 | S48: =S47&IF($L48<>"",$L48,$A48)&" " -> id screenout datum q1 q2_00 q2_01 q2_02 q2_03 q2_04 q2_05 q2_06 q2_07 q2_99 q3a q3b q3c q3d q3e q3f q3g q4 q6a q6b q6c q6d q6e q6f q6g q6h sel1 q7a1 q7a2 q7b1 q7b2 q7c1 q7c2 q7d1 q7d2 q7e1 q7e2 q7h1 q7h2 q7f1 q7f2 q7g1 q7g2 | T48: =ISERROR(FIND(" "&UPPER(IF($L48<>"",$L48,$A48))&" ",#REF!)) -> TRUE | V48: =IF(W48<>W49,W48,"") -> q7g | W48: =LEFT(IF($L48<>"",$L48,$A48),Y48) -> q7g | X48: =IF(W47=W48,X47,"")&IF(AND(OR(LEFT(H48,1)="F",K48="a",K48="n"),RIGHT(A48,2)<>"00",RIGHT(A48,2)<>"98",RIGHT(A48,2)<>"99"),IF($L48<>"",$L48,$A48)&" ","") -> q7g1 q7g2 | Y48: =Y47 -> 3
A49: q81 | B49: 129 | D49: Scale | E49: Input | F49: 5 | G49: Right | H49: F3 | I49: F3 | S49: =S48&IF($L49<>"",$L49,$A49)&" " -> id screenout datum q1 q2_00 q2_01 q2_02 q2_03 q2_04 q2_05 q2_06 q2_07 q2_99 q3a q3b q3c q3d q3e q3f q3g q4 q6a q6b q6c q6d q6e q6f q6g q6h sel1 q7a1 q7a2 q7b1 q7b2 q7c1 q7c2 q7d1 q7d2 q7e1 q7e2 q7h1 q7h2 q7f1 q7f2 q7g1 q7g2 q81 | T49: =ISERROR(FIND(" "&UPPER(IF($L49<>"",$L49,$A49))&" ",#REF!)) -> TRUE | V49: =IF(W49<>W50,W49,"") -> q81 | W49: =LEFT(IF($L49<>"",$L49,$A49),Y49) -> q81 | X49: =IF(W48=W49,X48,"")&IF(AND(OR(LEFT(H49,1)="F",K49="a",K49="n"),RIGHT(A49,2)<>"00",RIGHT(A49,2)<>"98",RIGHT(A49,2)<>"99"),IF($L49<>"",$L49,$A49)&" ","") -> q81 | Y49: =Y48 -> 3
A50: q82 | B50: 130 | D50: Scale | E50: Input | F50: 6 | G50: Right | H50: F3 | I50: F3 | S50: =S49&IF($L50<>"",$L50,$A50)&" " -> id screenout datum q1 q2_00 q2_01 q2_02 q2_03 q2_04 q2_05 q2_06 q2_07 q2_99 q3a q3b q3c q3d q3e q3f q3g q4 q6a q6b q6c q6d q6e q6f q6g q6h sel1 q7a1 q7a2 q7b1 q7b2 q7c1 q7c2 q7d1 q7d2 q7e1 q7e2 q7h1 q7h2 q7f1 q7f2 q7g1 q7g2 q81 q82 | T50: =ISERROR(FIND(" "&UPPER(IF($L50<>"",$L50,$A50))&" ",#REF!)) -> TRUE | V50: =IF(W50<>W51,W50,"") -> q82 | W50: =LEFT(IF($L50<>"",$L50,$A50),Y50) -> q82 | X50: =IF(W49=W50,X49,"")&IF(AND(OR(LEFT(H50,1)="F",K50="a",K50="n"),RIGHT(A50,2)<>"00",RIGHT(A50,2)<>"98",RIGHT(A50,2)<>"99"),IF($L50<>"",$L50,$A50)&" ","") -> q82 | Y50: =Y49 -> 3
A51: q91 | B51: 131 | D51: Scale | E51: Input | F51: 5 | G51: Right | H51: F3 | I51: F3 | S51: =S50&IF($L51<>"",$L51,$A51)&" " -> id screenout datum q1 q2_00 q2_01 q2_02 q2_03 q2_04 q2_05 q2_06 q2_07 q2_99 q3a q3b q3c q3d q3e q3f q3g q4 q6a q6b q6c q6d q6e q6f q6g q6h sel1 q7a1 q7a2 q7b1 q7b2 q7c1 q7c2 q7d1 q7d2 q7e1 q7e2 q7h1 q7h2 q7f1 q7f2 q7g1 q7g2 q81 q82 q91 | T51: =ISERROR(FIND(" "&UPPER(IF($L51<>"",$L51,$A51))&" ",#REF!)) -> TRUE | V51: =IF(W51<>W52,W51,"") -> q91 | W51: =LEFT(IF($L51<>"",$L51,$A51),Y51) -> q91 | X51: =IF(W50=W51,X50,"")&IF(AND(OR(LEFT(H51,1)="F",K51="a",K51="n"),RIGHT(A51,2)<>"00",RIGHT(A51,2)<>"98",RIGHT(A51,2)<>"99"),IF($L51<>"",$L51,$A51)&" ","") -> q91 | Y51: =Y50 -> 3
...

Sheet Label
A1: Variable Values | E1: Excecute before variable sheet? | F1: TRUE | G1: Summary variable | J1: Make new label
A2: Value | C2: Label | D2: New label | E2: Variable name | F2: Label length | G2: Variable Label | H2: Value | I2: Value Label | K2: Original variable label
A3: q1 | B3: -2 | E3: =IF(A3<>"",IF(V_LabelvorVariablen=TRUE,A3,IF(VLOOKUP(A3,V_VariablenEigenschaften,12,FALSE)="",A3,VLOOKUP(A3,V_VariablenEigenschaften,12,FALSE))),E2) -> q1 | F3: =LEN(C3) -> 0 | K3: =IF(A3<>"",VLOOKUP(A3,Variables!$A:$C,3,FALSE),"") -> 0
B4: 1 | E4: =IF(A4<>"",IF(V_LabelvorVariablen=TRUE,A4,IF(VLOOKUP(A4,V_VariablenEigenschaften,12,FALSE)="",A4,VLOOKUP(A4,V_VariablenEigenschaften,12,FALSE))),E3) -> q1 | F4: =LEN(C4) -> 0 | K4: =IF(A4<>"",VLOOKUP(A4,Variables!$A:$C,3,FALSE),"")
B5: 2 | E5: =IF(A5<>"",IF(V_LabelvorVariablen=TRUE,A5,IF(VLOOKUP(A5,V_VariablenEigenschaften,12,FALSE)="",A5,VLOOKUP(A5,V_VariablenEigenschaften,12,FALSE))),E4) -> q1 | F5: =LEN(C5) -> 0 | K5: =IF(A5<>"",VLOOKUP(A5,Variables!$A:$C,3,FALSE),"")
B6: 3 | E6: =IF(A6<>"",IF(V_LabelvorVariablen=TRUE,A6,IF(VLOOKUP(A6,V_VariablenEigenschaften,12,FALSE)="",A6,VLOOKUP(A6,V_VariablenEigenschaften,12,FALSE))),E5) -> q1 | F6: =LEN(C6) -> 0 | K6: =IF(A6<>"",VLOOKUP(A6,Variables!$A:$C,3,FALSE),"")
B7: 4 | E7: =IF(A7<>"",IF(V_LabelvorVariablen=TRUE,A7,IF(VLOOKUP(A7,V_VariablenEigenschaften,12,FALSE)="",A7,VLOOKUP(A7,V_VariablenEigenschaften,12,FALSE))),E6) -> q1 | F7: =LEN(C7) -> 0 | K7: =IF(A7<>"",VLOOKUP(A7,Variables!$A:$C,3,FALSE),"")
B8: 5 | E8: =IF(A8<>"",IF(V_LabelvorVariablen=TRUE,A8,IF(VLOOKUP(A8,V_VariablenEigenschaften,12,FALSE)="",A8,VLOOKUP(A8,V_VariablenEigenschaften,12,FALSE))),E7) -> q1 | F8: =LEN(C8) -> 0 | K8: =IF(A8<>"",VLOOKUP(A8,Variables!$A:$C,3,FALSE),"")
B9: 99 | E9: =IF(A9<>"",IF(V_LabelvorVariablen=TRUE,A9,IF(VLOOKUP(A9,V_VariablenEigenschaften,12,FALSE)="",A9,VLOOKUP(A9,V_VariablenEigenschaften,12,FALSE))),E8) -> q1 | F9: =LEN(C9) -> 0 | K9: =IF(A9<>"",VLOOKUP(A9,Variables!$A:$C,3,FALSE),"")
A10: q2_00 | B10: 0 | E10: =IF(A10<>"",IF(V_LabelvorVariablen=TRUE,A10,IF(VLOOKUP(A10,V_VariablenEigenschaften,12,FALSE)="",A10,VLOOKUP(A10,V_VariablenEigenschaften,12,FALSE))),E9) -> q2_00 | F10: =LEN(C10) -> 0 | K10: =IF(A10<>"",VLOOKUP(A10,Variables!$A:$C,3,FALSE),"") -> 0
B11: 1 | E11: =IF(A11<>"",IF(V_LabelvorVariablen=TRUE,A11,IF(VLOOKUP(A11,V_VariablenEigenschaften,12,FALSE)="",A11,VLOOKUP(A11,V_VariablenEigenschaften,12,FALSE))),E10) -> q2_00 | F11: =LEN(C11) -> 0 | K11: =IF(A11<>"",VLOOKUP(A11,Variables!$A:$C,3,FALSE),"")
A12: q2_01 | B12: 0 | E12: =IF(A12<>"",IF(V_LabelvorVariablen=TRUE,A12,IF(VLOOKUP(A12,V_VariablenEigenschaften,12,FALSE)="",A12,VLOOKUP(A12,V_VariablenEigenschaften,12,FALSE))),E11) -> q2_01 | F12: =LEN(C12) -> 0 | K12: =IF(A12<>"",VLOOKUP(A12,Variables!$A:$C,3,FALSE),"") -> 0
B13: 1 | E13: =IF(A13<>"",IF(V_LabelvorVariablen=TRUE,A13,IF(VLOOKUP(A13,V_VariablenEigenschaften,12,FALSE)="",A13,VLOOKUP(A13,V_VariablenEigenschaften,12,FALSE))),E12) -> q2_01 | F13: =LEN(C13) -> 0 | K13: =IF(A13<>"",VLOOKUP(A13,Variables!$A:$C,3,FALSE),"")
A14: q2_02 | B14: 0 | E14: =IF(A14<>"",IF(V_LabelvorVariablen=TRUE,A14,IF(VLOOKUP(A14,V_VariablenEigenschaften,12,FALSE)="",A14,VLOOKUP(A14,V_VariablenEigenschaften,12,FALSE))),E13) -> q2_02 | F14: =LEN(C14) -> 0 | K14: =IF(A14<>"",VLOOKUP(A14,Variables!$A:$C,3,FALSE),"") -> 0
B15: 1 | E15: =IF(A15<>"",IF(V_LabelvorVariablen=TRUE,A15,IF(VLOOKUP(A15,V_VariablenEigenschaften,12,FALSE)="",A15,VLOOKUP(A15,V_VariablenEigenschaften,12,FALSE))),E14) -> q2_02 | F15: =LEN(C15) -> 0 | K15: =IF(A15<>"",VLOOKUP(A15,Variables!$A:$C,3,FALSE),"")
A16: q2_03 | B16: 0 | E16: =IF(A16<>"",IF(V_LabelvorVariablen=TRUE,A16,IF(VLOOKUP(A16,V_VariablenEigenschaften,12,FALSE)="",A16,VLOOKUP(A16,V_VariablenEigenschaften,12,FALSE))),E15) -> q2_03 | F16: =LEN(C16) -> 0 | K16: =IF(A16<>"",VLOOKUP(A16,Variables!$A:$C,3,FALSE),"") -> 0
B17: 1 | E17: =IF(A17<>"",IF(V_LabelvorVariablen=TRUE,A17,IF(VLOOKUP(A17,V_VariablenEigenschaften,12,FALSE)="",A17,VLOOKUP(A17,V_VariablenEigenschaften,12,FALSE))),E16) -> q2_03 | F17: =LEN(C17) -> 0 | K17: =IF(A17<>"",VLOOKUP(A17,Variables!$A:$C,3,FALSE),"")
A18: q2_04 | B18: 0 | E18: =IF(A18<>"",IF(V_LabelvorVariablen=TRUE,A18,IF(VLOOKUP(A18,V_VariablenEigenschaften,12,FALSE)="",A18,VLOOKUP(A18,V_VariablenEigenschaften,12,FALSE))),E17) -> q2_04 | F18: =LEN(C18) -> 0 | K18: =IF(A18<>"",VLOOKUP(A18,Variables!$A:$C,3,FALSE),"") -> 0
B19: 1 | E19: =IF(A19<>"",IF(V_LabelvorVariablen=TRUE,A19,IF(VLOOKUP(A19,V_VariablenEigenschaften,12,FALSE)="",A19,VLOOKUP(A19,V_VariablenEigenschaften,12,FALSE))),E18) -> q2_04 | F19: =LEN(C19) -> 0 | K19: =IF(A19<>"",VLOOKUP(A19,Variables!$A:$C,3,FALSE),"")
A20: q2_05 | B20: 0 | E20: =IF(A20<>"",IF(V_LabelvorVariablen=TRUE,A20,IF(VLOOKUP(A20,V_VariablenEigenschaften,12,FALSE)="",A20,VLOOKUP(A20,V_VariablenEigenschaften,12,FALSE))),E19) -> q2_05 | F20: =LEN(C20) -> 0 | K20: =IF(A20<>"",VLOOKUP(A20,Variables!$A:$C,3,FALSE),"") -> 0
B21: 1 | E21: =IF(A21<>"",IF(V_LabelvorVariablen=TRUE,A21,IF(VLOOKUP(A21,V_VariablenEigenschaften,12,FALSE)="",A21,VLOOKUP(A21,V_VariablenEigenschaften,12,FALSE))),E20) -> q2_05 | F21: =LEN(C21) -> 0 | K21: =IF(A21<>"",VLOOKUP(A21,Variables!$A:$C,3,FALSE),"")
A22: q2_06 | B22: 0 | E22: =IF(A22<>"",IF(V_LabelvorVariablen=TRUE,A22,IF(VLOOKUP(A22,V_VariablenEigenschaften,12,FALSE)="",A22,VLOOKUP(A22,V_VariablenEigenschaften,12,FALSE))),E21) -> q2_06 | F22: =LEN(C22) -> 0 | K22: =IF(A22<>"",VLOOKUP(A22,Variables!$A:$C,3,FALSE),"") -> 0
B23: 1 | E23: =IF(A23<>"",IF(V_LabelvorVariablen=TRUE,A23,IF(VLOOKUP(A23,V_VariablenEigenschaften,12,FALSE)="",A23,VLOOKUP(A23,V_VariablenEigenschaften,12,FALSE))),E22) -> q2_06 | F23: =LEN(C23) -> 0 | K23: =IF(A23<>"",VLOOKUP(A23,Variables!$A:$C,3,FALSE),"")
A24: q2_07 | B24: 0 | E24: =IF(A24<>"",IF(V_LabelvorVariablen=TRUE,A24,IF(VLOOKUP(A24,V_VariablenEigenschaften,12,FALSE)="",A24,VLOOKUP(A24,V_VariablenEigenschaften,12,FALSE))),E23) -> q2_07 | F24: =LEN(C24) -> 0 | K24: =IF(A24<>"",VLOOKUP(A24,Variables!$A:$C,3,FALSE),"") -> 0
B25: 1 | E25: =IF(A25<>"",IF(V_LabelvorVariablen=TRUE,A25,IF(VLOOKUP(A25,V_VariablenEigenschaften,12,FALSE)="",A25,VLOOKUP(A25,V_VariablenEigenschaften,12,FALSE))),E24) -> q2_07 | F25: =LEN(C25) -> 0 | K25: =IF(A25<>"",VLOOKUP(A25,Variables!$A:$C,3,FALSE),"")
A26: q2_99 | B26: 0 | E26: =IF(A26<>"",IF(V_LabelvorVariablen=TRUE,A26,IF(VLOOKUP(A26,V_VariablenEigenschaften,12,FALSE)="",A26,VLOOKUP(A26,V_VariablenEigenschaften,12,FALSE))),E25) -> q2_99 | F26: =LEN(C26) -> 0 | K26: =IF(A26<>"",VLOOKUP(A26,Variables!$A:$C,3,FALSE),"") -> 0
B27: 1 | E27: =IF(A27<>"",IF(V_LabelvorVariablen=TRUE,A27,IF(VLOOKUP(A27,V_VariablenEigenschaften,12,FALSE)="",A27,VLOOKUP(A27,V_VariablenEigenschaften,12,FALSE))),E26) -> q2_99 | F27: =LEN(C27) -> 0 | K27: =IF(A27<>"",VLOOKUP(A27,Variables!$A:$C,3,FALSE),"")
A28: q3a | B28: -2 | E28: =IF(A28<>"",IF(V_LabelvorVariablen=TRUE,A28,IF(VLOOKUP(A28,V_VariablenEigenschaften,12,FALSE)="",A28,VLOOKUP(A28,V_VariablenEigenschaften,12,FALSE))),E27) -> q3a | F28: =LEN(C28) -> 0 | K28: =IF(A28<>"",VLOOKUP(A28,Variables!$A:$C,3,FALSE),"") -> 0
A29: q3b | B29: -2 | E29: =IF(A29<>"",IF(V_LabelvorVariablen=TRUE,A29,IF(VLOOKUP(A29,V_VariablenEigenschaften,12,FALSE)="",A29,VLOOKUP(A29,V_VariablenEigenschaften,12,FALSE))),E28) -> q3b | F29: =LEN(C29) -> 0 | K29: =IF(A29<>"",VLOOKUP(A29,Variables!$A:$C,3,FALSE),"") -> 0
A30: q3c | B30: -2 | E30: =IF(A30<>"",IF(V_LabelvorVariablen=TRUE,A30,IF(VLOOKUP(A30,V_VariablenEigenschaften,12,FALSE)="",A30,VLOOKUP(A30,V_VariablenEigenschaften,12,FALSE))),E29) -> q3c | F30: =LEN(C30) -> 0 | K30: =IF(A30<>"",VLOOKUP(A30,Variables!$A:$C,3,FALSE),"") -> 0
A31: q3d | B31: -2 | E31: =IF(A31<>"",IF(V_LabelvorVariablen=TRUE,A31,IF(VLOOKUP(A31,V_VariablenEigenschaften,12,FALSE)="",A31,VLOOKUP(A31,V_VariablenEigenschaften,12,FALSE))),E30) -> q3d | F31: =LEN(C31) -> 0 | K31: =IF(A31<>"",VLOOKUP(A31,Variables!$A:$C,3,FALSE),"") -> 0
A32: q3e | B32: -2 | E32: =IF(A32<>"",IF(V_LabelvorVariablen=TRUE,A32,IF(VLOOKUP(A32,V_VariablenEigenschaften,12,FALSE)="",A32,VLOOKUP(A32,V_VariablenEigenschaften,12,FALSE))),E31) -> q3e | F32: =LEN(C32) -> 0 | K32: =IF(A32<>"",VLOOKUP(A32,Variables!$A:$C,3,FALSE),"") -> 0
A33: q3f | B33: -2 | E33: =IF(A33<>"",IF(V_LabelvorVariablen=TRUE,A33,IF(VLOOKUP(A33,V_VariablenEigenschaften,12,FALSE)="",A33,VLOOKUP(A33,V_VariablenEigenschaften,12,FALSE))),E32) -> q3f | F33: =LEN(C33) -> 0 | K33: =IF(A33<>"",VLOOKUP(A33,Variables!$A:$C,3,FALSE),"") -> 0
A34: q3g | B34: -2 | E34: =IF(A34<>"",IF(V_LabelvorVariablen=TRUE,A34,IF(VLOOKUP(A34,V_VariablenEigenschaften,12,FALSE)="",A34,VLOOKUP(A34,V_VariablenEigenschaften,12,FALSE))),E33) -> q3g | F34: =LEN(C34) -> 0 | K34: =IF(A34<>"",VLOOKUP(A34,Variables!$A:$C,3,FALSE),"") -> 0
A35: q4 | B35: -3 | E35: =IF(A35<>"",IF(V_LabelvorVariablen=TRUE,A35,IF(VLOOKUP(A35,V_VariablenEigenschaften,12,FALSE)="",A35,VLOOKUP(A35,V_VariablenEigenschaften,12,FALSE))),E34) -> q4 | F35: =LEN(C35) -> 0 | K35: =IF(A35<>"",VLOOKUP(A35,Variables!$A:$C,3,FALSE),"") -> 0
B36: -2 | E36: =IF(A36<>"",IF(V_LabelvorVariablen=TRUE,A36,IF(VLOOKUP(A36,V_VariablenEigenschaften,12,FALSE)="",A36,VLOOKUP(A36,V_VariablenEigenschaften,12,FALSE))),E35) -> q4 | F36: =LEN(C36) -> 0 | K36: =IF(A36<>"",VLOOKUP(A36,Variables!$A:$C,3,FALSE),"")
B37: -1 | E37: =IF(A37<>"",IF(V_LabelvorVariablen=TRUE,A37,IF(VLOOKUP(A37,V_VariablenEigenschaften,12,FALSE)="",A37,VLOOKUP(A37,V_VariablenEigenschaften,12,FALSE))),E36) -> q4 | F37: =LEN(C37) -> 0 | K37: =IF(A37<>"",VLOOKUP(A37,Variables!$A:$C,3,FALSE),"")
A38: q6a | B38: -2 | E38: =IF(A38<>"",IF(V_LabelvorVariablen=TRUE,A38,IF(VLOOKUP(A38,V_VariablenEigenschaften,12,FALSE)="",A38,VLOOKUP(A38,V_VariablenEigenschaften,12,FALSE))),E37) -> q6a | F38: =LEN(C38) -> 0 | K38: =IF(A38<>"",VLOOKUP(A38,Variables!$A:$C,3,FALSE),"") -> 0
B39: 1 | D39: völlig unwichtig | E39: =IF(A39<>"",IF(V_LabelvorVariablen=TRUE,A39,IF(VLOOKUP(A39,V_VariablenEigenschaften,12,FALSE)="",A39,VLOOKUP(A39,V_VariablenEigenschaften,12,FALSE))),E38) -> q6a | F39: =LEN(C39) -> 0 | K39: =IF(A39<>"",VLOOKUP(A39,Variables!$A:$C,3,FALSE),"")
B40: 2 | D40: unwichtig | E40: =IF(A40<>"",IF(V_LabelvorVariablen=TRUE,A40,IF(VLOOKUP(A40,V_VariablenEigenschaften,12,FALSE)="",A40,VLOOKUP(A40,V_VariablenEigenschaften,12,FALSE))),E39) -> q6a | F40: =LEN(C40) -> 0 | K40: =IF(A40<>"",VLOOKUP(A40,Variables!$A:$C,3,FALSE),"")
...

Sheet Verbatims
B4: Verbatims file | D4: Daten\10_MergeFiles.xlsx
B5: ID-Variable | D5: DC_ID
B6: ID-Format
B7: Replace
B9: Filename result | D9: =V_Projektverzeichnis&"Verbatims\Verbatims_"&V_Projektname&"_"&V_Datum&".xlsx" -> #NAME?
B10: Filename input
B12: Read from line | D12: 2
B13: Read to line
H15: =MID(B15,3,100)&IF(C15=2,"n{nn}",IF(C15=3,"_{nn}","")) | R15: =IF(D15<>"",D15,"")
B18: VariableOriginal | C18: EFA1MCG2MDG3 | D18: Tabellen-blatt | E18: Nebeneinander? | F18: VariableOriginal | G18: VarOrigMissing | H18: VariableZiel | I18: VariableZähler | J18: VariableLabel | K18: VariableMissing | L18: Max.Codestufen | M18: CodestufenLabel | N18: Reserved | O18: Max.Zuordnungen | P18: BisherigerWertAnzeigen? | Q18: WeitereVariablen | R18: Titel
B19: o_q5 | C19: 2 | D19: Q5 | H19: =MID(B19,3,100)&IF(C19=2,"n{nn}",IF(C19=3,"_{nn}","")) -> q5n{nn} | L19: 100 | R19: =IF(D19<>"",D19,"") -> Q5

Sheet Free1
A2: #COMP | B2: sel0 | C2: 34
A3: #DIC | B3: sel1 | C3: sel0
A7: #REC | B7: q4 | C7: kq4 | D7: Tabellenbände pro Jahr
B8: 1 | C8: 2 | D8: 1 | E8: 1-2mal | F8: ="("&B8&IF(C8<>""," THRU "&C8,"")&" = "&D8&") " -> (1 THRU 2 = 1) | G8: =D8&" '"&E8&"' " -> 1 '1-2mal' | H8: =H7&F8 -> (1 THRU 2 = 1) | I8: =I7&G8 -> 1 '1-2mal'
B9: 3 | C9: 5 | D9: 2 | E9: 3-5mal | F9: ="("&B9&IF(C9<>""," THRU "&C9,"")&" = "&D9&") " -> (3 THRU 5 = 2) | G9: =D9&" '"&E9&"' " -> 2 '3-5mal' | H9: =H8&F9 -> (1 THRU 2 = 1) (3 THRU 5 = 2) | I9: =I8&G9 -> 1 '1-2mal' 2 '3-5mal'
A10: . | B10: 6 | C10: 999999 | D10: 3 | E10: >5mal | F10: ="("&B10&IF(C10<>""," THRU "&C10,"")&" = "&D10&") " -> (6 THRU 999999 = 3) | G10: =D10&" '"&E10&"' " -> 3 '>5mal' | H10: =H9&F10 -> (1 THRU 2 = 1) (3 THRU 5 = 2) (6 THRU 999999 = 3) | I10: =I9&G10 -> 1 '1-2mal' 2 '3-5mal' 3 '>5mal'
A14: #REC | B14: q10 | C14: kq10 | D14: Alter
B15: 18 | C15: 39 | D15: 1 | E15: 18 bis 39 | F15: ="("&B15&IF(C15<>""," THRU "&C15,"")&" = "&D15&") " -> (18 THRU 39 = 1) | G15: =D15&" '"&E15&"' " -> 1 '18 bis 39' | H15: =H14&F15 -> (18 THRU 39 = 1) | I15: =I14&G15 -> 1 '18 bis 39'
B16: 40 | C16: 49 | D16: 2 | E16: 40 bis 49 | F16: ="("&B16&IF(C16<>""," THRU "&C16,"")&" = "&D16&") " -> (40 THRU 49 = 2) | G16: =D16&" '"&E16&"' " -> 2 '40 bis 49' | H16: =H15&F16 -> (18 THRU 39 = 1) (40 THRU 49 = 2) | I16: =I15&G16 -> 1 '18 bis 39' 2 '40 bis 49'
A17: . | B17: 50 | C17: 97 | D17: 3 | E17: 50 und älter | F17: ="("&B17&IF(C17<>""," THRU "&C17,"")&" = "&D17&") " -> (50 THRU 97 = 3) | G17: =D17&" '"&E17&"' " -> 3 '50 und älter' | H17: =H16&F17 -> (18 THRU 39 = 1) (40 THRU 49 = 2) (50 THRU 97 = 3) | I17: =I16&G17 -> 1 '18 bis 39' 2 '40 bis 49' 3 '50 und älter'
A19: #KG | B19: kq4 | C19: kq10
A20: #KG | B20: kq4 | C20: regio
A29: #REC | B29: sel0 sel1
B30: 34 | D30: 1
B31: 14 | D31: 2
B32: 32 | D32: 3
B33: 7 | C33: 20 | D33: 4
B34: 21 | C34: 30 | D34: 5
B35: 31 | C35: 97 | D35: 6
A36: . | B36: 99 | D36: 7
A38: #COMP | B38: gew | C38: 1
A39: #IF | B39: DC_ID <= 31190 | C39: gew = .5
A40: #IF | B40: DC_ID >= 44737 | C40: gew = 2

Sheet Free2
A6: #COMP | B6: q5n{1 2 3 4 5} | C6: -2 | E6: COMPUTE q5n1 = -2.
E7: COMPUTE q5n2 = -2.
E8: COMPUTE q5n3 = -2.
E9: COMPUTE q5n4 = -2.
E10: COMPUTE q5n5 = -2.
A20: #IF | B20: DC_ID == 21503 | C20: q5n1 = 3
A21: #IF | B21: DC_ID == 29779 | C21: q5n1 = 2
A22: #IF | B22: DC_ID == 31190 | C22: q5n1 = 97
A23: #IF | B23: DC_ID == 27542 | C23: q5n1 = 97
A24: #IF | B24: DC_ID == 27145 | C24: q5n1 = 1
A25: #IF | B25: DC_ID == 43307 | C25: q5n1 = 5
A26: #IF | B26: DC_ID == 10014 | C26: q5n1 = 2
A27: #IF | B27: DC_ID == 56856 | C27: q5n1 = 5
A28: #IF | B28: DC_ID == 31956 | C28: q5n1 = 6
A29: #IF | B29: DC_ID == 52542 | C29: q5n1 = 4
A30: #IF | B30: DC_ID == 15545 | C30: q5n1 = 4
A31: #IF | B31: DC_ID == 56032 | C31: q5n1 = 2
... A257: #IF | B257: q5n1==-2 | C257: q5n1=99
A260: #REC | B260: q5n1 q5n2 q5n3 q5n4 q5n5
A261: . | B261: 5 | C261: 7 | D261: 5
A266: #VALL | B266: q5n1 q5n2 q5n3 q5n4 q5n5 | E266: VALUE LABEL -2 'FILTER'
B267: 1 | C267: =SUBSTITUTE(MID(E267,4,100),"'","") -> Freundlichkeit des Tabellenbanderstellers | E267: 1 'Freundlichkeit des Tabellenbanderstellers'
B268: 2 | C268: =SUBSTITUTE(MID(E268,4,100),"'","") -> Kompetenz | E268: 2 'Kompetenz'
B269: 3 | C269: =SUBSTITUTE(MID(E269,4,100),"'","") -> Schnelligkeit der Umsetzung | E269: 3 'Schnelligkeit der Umsetzung'
B270: 4 | C270: =SUBSTITUTE(MID(E270,4,100),"'","") -> Darstellung der Daten | E270: 4 'Darstellung der Daten'
B271: 5 | C271: =SUBSTITUTE(MID(E271,4,100),"'","") -> einfache Weiterverarbeitung der Daten | E271: 5 'einfache Weiterverarbeitung der Daten'
B272: 97 | C272: =SUBSTITUTE(MID(E272,4,100),"'","") -> Sonstiges | E272: 97 'Sonstiges'
A273: . | B273: 99 | C273: =SUBSTITUTE(MID(E273,4,100),"'","") -> Keine Angabe | E273: 99 'Keine Angabe'

Sheet Tabelle1
