Workbook
Name V_AnzVariablen: 'Q6'!$H$5
Name V_AnzVariablen: 'Q7'!$H$5
Name V_B_Q6_AnzZuord: 'Q6'!$D$14
Name V_B_Q6_AnzZuordOVerb: 'Q6'!$D$18
Name V_B_Q6_Codestufen: 'Q6'!$D$22
Name V_B_Q6_CodestufenName: 'Q6'!$D$20
Name V_B_Q6_Datensaetze: 'Q6'!$D$8
Name V_B_Q6_Verbatims: 'Q6'!$D$10
Name V_B_Q6_Zuord: 'Q6'!$D$12
Name V_B_Q7_AnzZuord: 'Q7'!$D$14
Name V_B_Q7_AnzZuordOVerb: 'Q7'!$D$18
Name V_B_Q7_Codestufen: 'Q7'!$D$22
Name V_B_Q7_CodestufenName: 'Q7'!$D$20
Name V_B_Q7_Datensaetze: 'Q7'!$D$8
Name V_B_Q7_Verbatims: 'Q7'!$D$10
Name V_B_Q7_Zuord: 'Q7'!$D$12
Name V_W_Q6_AnzZuord: 'Q6'!$I$33:$I$132
Name V_W_Q6_AnzZuordOVerb: 'Q6'!$K$33:$K$132
Name V_W_Q6_Codestufen: 'Q6'!$C$1:$C$100
Name V_W_Q6_CodestufenName: 'Q6'!$B$1:$B$100
Name V_W_Q6_Datensaetze: 'Q6'!$D$33:$D$132
Name V_W_Q6_Verbatims: 'Q6'!$H$33:$H$132
Name V_W_Q6_Zuord: 'Q6'!$G$33:$G$132
Name V_W_Q7_AnzZuord: 'Q7'!$I$33:$I$132
Name V_W_Q7_AnzZuordOVerb: 'Q7'!$K$33:$K$132
Name V_W_Q7_Codestufen: 'Q7'!$C$1:$C$100
Name V_W_Q7_CodestufenName: 'Q7'!$B$1:$B$100
Name V_W_Q7_Datensaetze: 'Q7'!$D$33:$D$132
Name V_W_Q7_Verbatims: 'Q7'!$H$33:$H$132
Name V_W_Q7_Zuord: 'Q7'!$G$33:$G$132

Sheet Codestufen
B1: =HYPERLINK("#'Q6'!D1","Q6") -> Q6 | C1: =HYPERLINK("#'Q7'!D1","Q7") -> Q7
A2: 1 | B2: love | C2: sadness
A3: =A2+1 -> 2 | B3: joy | C3: fear
A4: =A3+1 -> 3 | B4: happiness | C4: anger
A5: =A4+1 -> 4 | C5: pain
A6: =A5+1 -> 5
A7: =A6+1 -> 6
A8: =A7+1 -> 7
A9: =A8+1 -> 8
A10: =A9+1 -> 9
A11: =A10+1 -> 10
A12: =A11+1 -> 11
A13: =A12+1 -> 12
A14: =A13+1 -> 13
A15: =A14+1 -> 14
A16: =A15+1 -> 15
A17: =A16+1 -> 16
... A1001: =A1000+1 -> 1000

Sheet Q6
A1: 1 | B1: =Codestufen!B2 -> love | C1: =COUNTIF(V_W_Q6_Zuord,A1) -> 31 | D1: Q6
A2: 2 | B2: =Codestufen!B3 -> joy | C2: =COUNTIF(V_W_Q6_Zuord,A2) -> 41
A3: 3 | B3: =Codestufen!B4 -> happiness | C3: =COUNTIF(V_W_Q6_Zuord,A3) -> 28 | D3: 4 | E3: Code | F3: Beschreibung | G3: Anzahl | H3: Übersicht
A4: 4 | B4: =Codestufen!B5 -> 0 | C4: =COUNTIF(V_W_Q6_Zuord,A4) -> 0 | F4: ="Zuordnungen < "&E5 -> Zuordnungen < 1 | G4: =COUNTIF(V_W_Q6_Zuord,"<"&E5) -> 0 | H4: =COUNTA(V_W_Q6_Datensaetze)/H5 -> 100 | I4: Datensätze
A5: 5 | B5: =Codestufen!B6 -> 0 | C5: =COUNTIF(V_W_Q6_Zuord,A5) -> 0 | D5: Codestufenspalte | E5: =(4-D3)*20+1 -> 1 | F5: =HYPERLINK("#Codestufen!"&ADDRESS(E5+1,D$6),IF(INDEX(V_W_Q6_CodestufenName,E5)=0,"",INDEX(V_W_Q6_CodestufenName,E5))) -> love | G5: =INDEX(V_W_Q6_Codestufen,E5) -> 31 | H5: 1 | I5: Variablen
A6: 6 | B6: =Codestufen!B7 -> 0 | C6: =COUNTIF(V_W_Q6_Zuord,A6) -> 0 | D6: 2 | E6: =E5+1 -> 2 | F6: =HYPERLINK("#Codestufen!"&ADDRESS(E6+1,D$6),IF(INDEX(V_W_Q6_CodestufenName,E6)=0,"",INDEX(V_W_Q6_CodestufenName,E6))) -> joy | G6: =INDEX(V_W_Q6_Codestufen,E6) -> 41 | H6: =SUM(V_W_Q6_Verbatims) -> 100 | I6: Verbatims
A7: 7 | B7: =Codestufen!B8 -> 0 | C7: =COUNTIF(V_W_Q6_Zuord,A7) -> 0 | D7: Datensätze | E7: =E6+1 -> 3 | F7: =HYPERLINK("#Codestufen!"&ADDRESS(E7+1,D$6),IF(INDEX(V_W_Q6_CodestufenName,E7)=0,"",INDEX(V_W_Q6_CodestufenName,E7))) -> happiness | G7: =INDEX(V_W_Q6_Codestufen,E7) -> 28 | H7: =COUNTIF(V_W_Q6_AnzZuord,">0") -> 100 | I7: Zuordnungen
A8: 8 | B8: =Codestufen!B9 -> 0 | C8: =COUNTIF(V_W_Q6_Zuord,A8) -> 0 | D8: ="D33:D"&D24 -> D33:D132 | E8: =E7+1 -> 4 | F8: =HYPERLINK("#Codestufen!"&ADDRESS(E8+1,D$6),IF(INDEX(V_W_Q6_CodestufenName,E8)=0,"",INDEX(V_W_Q6_CodestufenName,E8))) | G8: =INDEX(V_W_Q6_Codestufen,E8) -> 0 | H8: =SUM(V_W_Q6_AnzZuord) -> 100 | I8: Nennungen
A9: 9 | B9: =Codestufen!B10 -> 0 | C9: =COUNTIF(V_W_Q6_Zuord,A9) -> 0 | D9: Verbatims | E9: =E8+1 -> 5 | F9: =HYPERLINK("#Codestufen!"&ADDRESS(E9+1,D$6),IF(INDEX(V_W_Q6_CodestufenName,E9)=0,"",INDEX(V_W_Q6_CodestufenName,E9))) | G9: =INDEX(V_W_Q6_Codestufen,E9) -> 0
A10: 10 | B10: =Codestufen!B11 -> 0 | C10: =COUNTIF(V_W_Q6_Zuord,A10) -> 0 | D10: ="H33:H"&D24 -> H33:H132 | E10: =E9+1 -> 6 | F10: =HYPERLINK("#Codestufen!"&ADDRESS(E10+1,D$6),IF(INDEX(V_W_Q6_CodestufenName,E10)=0,"",INDEX(V_W_Q6_CodestufenName,E10))) | G10: =INDEX(V_W_Q6_Codestufen,E10) -> 0 | H10: Status
A11: 11 | B11: =Codestufen!B12 -> 0 | C11: =COUNTIF(V_W_Q6_Zuord,A11) -> 0 | D11: Zuordnungen | E11: =E10+1 -> 7 | F11: =HYPERLINK("#Codestufen!"&ADDRESS(E11+1,D$6),IF(INDEX(V_W_Q6_CodestufenName,E11)=0,"",INDEX(V_W_Q6_CodestufenName,E11))) | G11: =INDEX(V_W_Q6_Codestufen,E11) -> 0 | H11: =H6-H7&" Verbatims sind noch zuzuordnen" -> 0 Verbatims sind noch zuzuordnen
A12: 12 | B12: =Codestufen!B13 -> 0 | C12: =COUNTIF(V_W_Q6_Zuord,A12) -> 0 | D12: ="G33:G"&D24 -> G33:G132 | E12: =E11+1 -> 8 | F12: =HYPERLINK("#Codestufen!"&ADDRESS(E12+1,D$6),IF(INDEX(V_W_Q6_CodestufenName,E12)=0,"",INDEX(V_W_Q6_CodestufenName,E12))) | G12: =INDEX(V_W_Q6_Codestufen,E12) -> 0
A13: 13 | B13: =Codestufen!B14 -> 0 | C13: =COUNTIF(V_W_Q6_Zuord,A13) -> 0 | D13: Anzahl Zuordnungen | E13: =E12+1 -> 9 | F13: =HYPERLINK("#Codestufen!"&ADDRESS(E13+1,D$6),IF(INDEX(V_W_Q6_CodestufenName,E13)=0,"",INDEX(V_W_Q6_CodestufenName,E13))) | G13: =INDEX(V_W_Q6_Codestufen,E13) -> 0
A14: 14 | B14: =Codestufen!B15 -> 0 | C14: =COUNTIF(V_W_Q6_Zuord,A14) -> 0 | D14: ="I33:I"&D24 -> I33:I132 | E14: =E13+1 -> 10 | F14: =HYPERLINK("#Codestufen!"&ADDRESS(E14+1,D$6),IF(INDEX(V_W_Q6_CodestufenName,E14)=0,"",INDEX(V_W_Q6_CodestufenName,E14))) | G14: =INDEX(V_W_Q6_Codestufen,E14) -> 0
A15: 15 | B15: =Codestufen!B16 -> 0 | C15: =COUNTIF(V_W_Q6_Zuord,A15) -> 0 | D15: Anzahl ohne Zuordnung | E15: =E14+1 -> 11 | F15: =HYPERLINK("#Codestufen!"&ADDRESS(E15+1,D$6),IF(INDEX(V_W_Q6_CodestufenName,E15)=0,"",INDEX(V_W_Q6_CodestufenName,E15))) | G15: =INDEX(V_W_Q6_Codestufen,E15) -> 0
A16: 16 | B16: =Codestufen!B17 -> 0 | C16: =COUNTIF(V_W_Q6_Zuord,A16) -> 0 | D16: ="J33:J"&D24 -> J33:J132 | E16: =E15+1 -> 12 | F16: =HYPERLINK("#Codestufen!"&ADDRESS(E16+1,D$6),IF(INDEX(V_W_Q6_CodestufenName,E16)=0,"",INDEX(V_W_Q6_CodestufenName,E16))) | G16: =INDEX(V_W_Q6_Codestufen,E16) -> 0
A17: 17 | B17: =Codestufen!B18 -> 0 | C17: =COUNTIF(V_W_Q6_Zuord,A17) -> 0 | D17: Anzahl Zuordnungen ohne Verbatim | E17: =E16+1 -> 13 | F17: =HYPERLINK("#Codestufen!"&ADDRESS(E17+1,D$6),IF(INDEX(V_W_Q6_CodestufenName,E17)=0,"",INDEX(V_W_Q6_CodestufenName,E17))) | G17: =INDEX(V_W_Q6_Codestufen,E17) -> 0 | H17: =IF(SUM(V_W_Q6_Codestufen)<>SUMIF(V_W_Q6_CodestufenName,"<>0",V_W_Q6_Codestufen),"Es gibt Nennungen, die keinem Code zugeordnet werden können.","")&IF(SUM(V_W_Q6_AnzZuordOVerb)>0,"Es gibt Zuordnungen bei nicht vorhandenen Verbatims.","")
A18: 18 | B18: =Codestufen!B19 -> 0 | C18: =COUNTIF(V_W_Q6_Zuord,A18) -> 0 | D18: ="K33:K"&D24 -> K33:K132 | E18: =E17+1 -> 14 | F18: =HYPERLINK("#Codestufen!"&ADDRESS(E18+1,D$6),IF(INDEX(V_W_Q6_CodestufenName,E18)=0,"",INDEX(V_W_Q6_CodestufenName,E18))) | G18: =INDEX(V_W_Q6_Codestufen,E18) -> 0
A19: 19 | B19: =Codestufen!B20 -> 0 | C19: =COUNTIF(V_W_Q6_Zuord,A19) -> 0 | D19: Codestufen Name | E19: =E18+1 -> 15 | F19: =HYPERLINK("#Codestufen!"&ADDRESS(E19+1,D$6),IF(INDEX(V_W_Q6_CodestufenName,E19)=0,"",INDEX(V_W_Q6_CodestufenName,E19))) | G19: =INDEX(V_W_Q6_Codestufen,E19) -> 0
A20: 20 | B20: =Codestufen!B21 -> 0 | C20: =COUNTIF(V_W_Q6_Zuord,A20) -> 0 | D20: B1:B100 | E20: =E19+1 -> 16 | F20: =HYPERLINK("#Codestufen!"&ADDRESS(E20+1,D$6),IF(INDEX(V_W_Q6_CodestufenName,E20)=0,"",INDEX(V_W_Q6_CodestufenName,E20))) | G20: =INDEX(V_W_Q6_Codestufen,E20) -> 0
A21: 21 | B21: =Codestufen!B22 -> 0 | C21: =COUNTIF(V_W_Q6_Zuord,A21) -> 0 | D21: Codestufen Anzahl | E21: =E20+1 -> 17 | F21: =HYPERLINK("#Codestufen!"&ADDRESS(E21+1,D$6),IF(INDEX(V_W_Q6_CodestufenName,E21)=0,"",INDEX(V_W_Q6_CodestufenName,E21))) | G21: =INDEX(V_W_Q6_Codestufen,E21) -> 0
A22: 22 | B22: =Codestufen!B23 -> 0 | C22: =COUNTIF(V_W_Q6_Zuord,A22) -> 0 | D22: C1:C100 | E22: =E21+1 -> 18 | F22: =HYPERLINK("#Codestufen!"&ADDRESS(E22+1,D$6),IF(INDEX(V_W_Q6_CodestufenName,E22)=0,"",INDEX(V_W_Q6_CodestufenName,E22))) | G22: =INDEX(V_W_Q6_Codestufen,E22) -> 0
A23: 23 | B23: =Codestufen!B24 -> 0 | C23: =COUNTIF(V_W_Q6_Zuord,A23) -> 0 | D23: Letzte Zeile | E23: =E22+1 -> 19 | F23: =HYPERLINK("#Codestufen!"&ADDRESS(E23+1,D$6),IF(INDEX(V_W_Q6_CodestufenName,E23)=0,"",INDEX(V_W_Q6_CodestufenName,E23))) | G23: =INDEX(V_W_Q6_Codestufen,E23) -> 0
A24: 24 | B24: =Codestufen!B25 -> 0 | C24: =COUNTIF(V_W_Q6_Zuord,A24) -> 0 | D24: 132 | E24: =E23+1 -> 20 | F24: =HYPERLINK("#Codestufen!"&ADDRESS(E24+1,D$6),IF(INDEX(V_W_Q6_CodestufenName,E24)=0,"",INDEX(V_W_Q6_CodestufenName,E24))) | G24: =INDEX(V_W_Q6_Codestufen,E24) -> 0
A25: 25 | B25: =Codestufen!B26 -> 0 | C25: =COUNTIF(V_W_Q6_Zuord,A25) -> 0 | F25: ="Zuordnungen > " &E24& " und < "&E26 -> Zuordnungen > 20 und < 97 | G25: =COUNTIF(V_W_Q6_Zuord,"<"&E26)-SUM(G4:G24) -> 0
A26: 26 | B26: =Codestufen!B27 -> 0 | C26: =COUNTIF(V_W_Q6_Zuord,A26) -> 0 | D26: Feste | E26: =D29 -> 97 | F26: =HYPERLINK("#Codestufen!"&ADDRESS(E26+1,D$6),IF(INDEX(V_W_Q6_CodestufenName,E26)=0,"",INDEX(V_W_Q6_CodestufenName,E26))) | G26: =INDEX(V_W_Q6_Codestufen,E26) -> 0
A27: 27 | B27: =Codestufen!B28 -> 0 | C27: =COUNTIF(V_W_Q6_Zuord,A27) -> 0 | D27: Werte | E27: =E26+1 -> 98 | F27: =HYPERLINK("#Codestufen!"&ADDRESS(E27+1,D$6),IF(INDEX(V_W_Q6_CodestufenName,E27)=0,"",INDEX(V_W_Q6_CodestufenName,E27))) | G27: =INDEX(V_W_Q6_Codestufen,E27) -> 0
A28: 28 | B28: =Codestufen!B29 -> 0 | C28: =COUNTIF(V_W_Q6_Zuord,A28) -> 0 | D28: ab | E28: =E27+1 -> 99 | F28: =HYPERLINK("#Codestufen!"&ADDRESS(E28+1,D$6),IF(INDEX(V_W_Q6_CodestufenName,E28)=0,"",INDEX(V_W_Q6_CodestufenName,E28))) | G28: =INDEX(V_W_Q6_Codestufen,E28) -> 0
A29: 29 | B29: =Codestufen!B30 -> 0 | C29: =COUNTIF(V_W_Q6_Zuord,A29) -> 0 | D29: 97 | E29: =E28+1 -> 100 | F29: =HYPERLINK("#Codestufen!"&ADDRESS(E29+1,D$6),IF(INDEX(V_W_Q6_CodestufenName,E29)=0,"",INDEX(V_W_Q6_CodestufenName,E29))) | G29: =INDEX(V_W_Q6_Codestufen,E29) -> 0
A30: 30 | B30: =Codestufen!B31 -> 0 | C30: =COUNTIF(V_W_Q6_Zuord,A30) -> 0 | F30: ="Zuordnungen > " &E29 -> Zuordnungen > 100 | G30: =COUNTIF(V_W_Q6_Zuord,">"&E29) -> 0
A31: 31 | B31: =Codestufen!B32 -> 0 | C31: =COUNTIF(V_W_Q6_Zuord,A31) -> 0
A32: 32 | B32: =Codestufen!B33 -> 0 | C32: =COUNTIF(V_W_Q6_Zuord,A32) -> 0 | D32: Orig. Variable | E32: ID | F32: Antwort | G32: Zuord 1 | H32: Verbatim? | I32: Zuordnungen? | J32: Ohne Zuordnung | K32: Zuord. ohne Verb. | L32: CalcV1 | M32: CalcV2 | N32: CalcV3 | O32: Calc1 Zuord 1 | P32: Calc2 Zuord 1 | Q32: Calc3 Zuord 1 | R32: CalcN1 | S32: CalcN2 | T32: CalcN3
A33: 33 | B33: =Codestufen!B34 -> 0 | C33: =COUNTIF(V_W_Q6_Zuord,A33) -> 0 | D33: q6 | E33: 7 | F33: bla love | G33: 1 | H33: =IF(TRIM(F33)="",0,1) -> 1 | I33: =COUNT(G33:G33) -> 1 | J33: =IF(I33 >= H33,0,1) -> 0 | K33: =IF(AND(I33 > 0,H33=0),1,0) -> 0
A34: 34 | B34: =Codestufen!B35 -> 0 | C34: =COUNTIF(V_W_Q6_Zuord,A34) -> 0 | D34: q6 | E34: 17 | F34: bla love | G34: 1 | H34: =IF(TRIM(F34)="",0,1) -> 1 | I34: =COUNT(G34:G34) -> 1 | J34: =IF(I34 >= H34,0,1) -> 0 | K34: =IF(AND(I34 > 0,H34=0),1,0) -> 0
A35: 35 | B35: =Codestufen!B36 -> 0 | C35: =COUNTIF(V_W_Q6_Zuord,A35) -> 0 | D35: q6 | E35: 23 | F35: bla love | G35: 1 | H35: =IF(TRIM(F35)="",0,1) -> 1 | I35: =COUNT(G35:G35) -> 1 | J35: =IF(I35 >= H35,0,1) -> 0 | K35: =IF(AND(I35 > 0,H35=0),1,0) -> 0
A36: 36 | B36: =Codestufen!B37 -> 0 | C36: =COUNTIF(V_W_Q6_Zuord,A36) -> 0 | D36: q6 | E36: 51 | F36: bla love | G36: 1 | H36: =IF(TRIM(F36)="",0,1) -> 1 | I36: =COUNT(G36:G36) -> 1 | J36: =IF(I36 >= H36,0,1) -> 0 | K36: =IF(AND(I36 > 0,H36=0),1,0) -> 0
A37: 37 | B37: =Codestufen!B38 -> 0 | C37: =COUNTIF(V_W_Q6_Zuord,A37) -> 0 | D37: q6 | E37: 58 | F37: bla love | G37: 1 | H37: =IF(TRIM(F37)="",0,1) -> 1 | I37: =COUNT(G37:G37) -> 1 | J37: =IF(I37 >= H37,0,1) -> 0 | K37: =IF(AND(I37 > 0,H37=0),1,0) -> 0
A38: 38 | B38: =Codestufen!B39 -> 0 | C38: =COUNTIF(V_W_Q6_Zuord,A38) -> 0 | D38: q6 | E38: 65 | F38: bla love | G38: 1 | H38: =IF(TRIM(F38)="",0,1) -> 1 | I38: =COUNT(G38:G38) -> 1 | J38: =IF(I38 >= H38,0,1) -> 0 | K38: =IF(AND(I38 > 0,H38=0),1,0) -> 0
A39: 39 | B39: =Codestufen!B40 -> 0 | C39: =COUNTIF(V_W_Q6_Zuord,A39) -> 0 | D39: q6 | E39: 67 | F39: bla love | G39: 1 | H39: =IF(TRIM(F39)="",0,1) -> 1 | I39: =COUNT(G39:G39) -> 1 | J39: =IF(I39 >= H39,0,1) -> 0 | K39: =IF(AND(I39 > 0,H39=0),1,0) -> 0
A40: 40 | B40: =Codestufen!B41 -> 0 | C40: =COUNTIF(V_W_Q6_Zuord,A40) -> 0 | D40: q6 | E40: 73 | F40: bla love | G40: 1 | H40: =IF(TRIM(F40)="",0,1) -> 1 | I40: =COUNT(G40:G40) -> 1 | J40: =IF(I40 >= H40,0,1) -> 0 | K40: =IF(AND(I40 > 0,H40=0),1,0) -> 0
...

Sheet Q7
A1: 1 | B1: =Codestufen!C2 -> sadness | C1: =COUNTIF(V_W_Q7_Zuord,A1) -> 19 | D1: Q7
A2: 2 | B2: =Codestufen!C3 -> fear | C2: =COUNTIF(V_W_Q7_Zuord,A2) -> 27
A3: 3 | B3: =Codestufen!C4 -> anger | C3: =COUNTIF(V_W_Q7_Zuord,A3) -> 29 | D3: 4 | E3: Code | F3: Beschreibung | G3: Anzahl | H3: Übersicht
A4: 4 | B4: =Codestufen!C5 -> pain | C4: =COUNTIF(V_W_Q7_Zuord,A4) -> 25 | F4: ="Zuordnungen < "&E5 -> Zuordnungen < 1 | G4: =COUNTIF(V_W_Q7_Zuord,"<"&E5) -> 0 | H4: =COUNTA(V_W_Q7_Datensaetze)/H5 -> 100 | I4: Datensätze
A5: 5 | B5: =Codestufen!C6 -> 0 | C5: =COUNTIF(V_W_Q7_Zuord,A5) -> 0 | D5: Codestufenspalte | E5: =(4-D3)*20+1 -> 1 | F5: =HYPERLINK("#Codestufen!"&ADDRESS(E5+1,D$6),IF(INDEX(V_W_Q7_CodestufenName,E5)=0,"",INDEX(V_W_Q7_CodestufenName,E5))) -> sadness | G5: =INDEX(V_W_Q7_Codestufen,E5) -> 19 | H5: 1 | I5: Variablen
A6: 6 | B6: =Codestufen!C7 -> 0 | C6: =COUNTIF(V_W_Q7_Zuord,A6) -> 0 | D6: 3 | E6: =E5+1 -> 2 | F6: =HYPERLINK("#Codestufen!"&ADDRESS(E6+1,D$6),IF(INDEX(V_W_Q7_CodestufenName,E6)=0,"",INDEX(V_W_Q7_CodestufenName,E6))) -> fear | G6: =INDEX(V_W_Q7_Codestufen,E6) -> 27 | H6: =SUM(V_W_Q7_Verbatims) -> 100 | I6: Verbatims
A7: 7 | B7: =Codestufen!C8 -> 0 | C7: =COUNTIF(V_W_Q7_Zuord,A7) -> 0 | D7: Datensätze | E7: =E6+1 -> 3 | F7: =HYPERLINK("#Codestufen!"&ADDRESS(E7+1,D$6),IF(INDEX(V_W_Q7_CodestufenName,E7)=0,"",INDEX(V_W_Q7_CodestufenName,E7))) -> anger | G7: =INDEX(V_W_Q7_Codestufen,E7) -> 29 | H7: =COUNTIF(V_W_Q7_AnzZuord,">0") -> 100 | I7: Zuordnungen
A8: 8 | B8: =Codestufen!C9 -> 0 | C8: =COUNTIF(V_W_Q7_Zuord,A8) -> 0 | D8: ="D33:D"&D24 -> D33:D132 | E8: =E7+1 -> 4 | F8: =HYPERLINK("#Codestufen!"&ADDRESS(E8+1,D$6),IF(INDEX(V_W_Q7_CodestufenName,E8)=0,"",INDEX(V_W_Q7_CodestufenName,E8))) -> pain | G8: =INDEX(V_W_Q7_Codestufen,E8) -> 25 | H8: =SUM(V_W_Q7_AnzZuord) -> 100 | I8: Nennungen
A9: 9 | B9: =Codestufen!C10 -> 0 | C9: =COUNTIF(V_W_Q7_Zuord,A9) -> 0 | D9: Verbatims | E9: =E8+1 -> 5 | F9: =HYPERLINK("#Codestufen!"&ADDRESS(E9+1,D$6),IF(INDEX(V_W_Q7_CodestufenName,E9)=0,"",INDEX(V_W_Q7_CodestufenName,E9))) | G9: =INDEX(V_W_Q7_Codestufen,E9) -> 0
A10: 10 | B10: =Codestufen!C11 -> 0 | C10: =COUNTIF(V_W_Q7_Zuord,A10) -> 0 | D10: ="H33:H"&D24 -> H33:H132 | E10: =E9+1 -> 6 | F10: =HYPERLINK("#Codestufen!"&ADDRESS(E10+1,D$6),IF(INDEX(V_W_Q7_CodestufenName,E10)=0,"",INDEX(V_W_Q7_CodestufenName,E10))) | G10: =INDEX(V_W_Q7_Codestufen,E10) -> 0 | H10: Status
A11: 11 | B11: =Codestufen!C12 -> 0 | C11: =COUNTIF(V_W_Q7_Zuord,A11) -> 0 | D11: Zuordnungen | E11: =E10+1 -> 7 | F11: =HYPERLINK("#Codestufen!"&ADDRESS(E11+1,D$6),IF(INDEX(V_W_Q7_CodestufenName,E11)=0,"",INDEX(V_W_Q7_CodestufenName,E11))) | G11: =INDEX(V_W_Q7_Codestufen,E11) -> 0 | H11: =H6-H7&" Verbatims sind noch zuzuordnen" -> 0 Verbatims sind noch zuzuordnen
A12: 12 | B12: =Codestufen!C13 -> 0 | C12: =COUNTIF(V_W_Q7_Zuord,A12) -> 0 | D12: ="G33:G"&D24 -> G33:G132 | E12: =E11+1 -> 8 | F12: =HYPERLINK("#Codestufen!"&ADDRESS(E12+1,D$6),IF(INDEX(V_W_Q7_CodestufenName,E12)=0,"",INDEX(V_W_Q7_CodestufenName,E12))) | G12: =INDEX(V_W_Q7_Codestufen,E12) -> 0
A13: 13 | B13: =Codestufen!C14 -> 0 | C13: =COUNTIF(V_W_Q7_Zuord,A13) -> 0 | D13: Anzahl Zuordnungen | E13: =E12+1 -> 9 | F13: =HYPERLINK("#Codestufen!"&ADDRESS(E13+1,D$6),IF(INDEX(V_W_Q7_CodestufenName,E13)=0,"",INDEX(V_W_Q7_CodestufenName,E13))) | G13: =INDEX(V_W_Q7_Codestufen,E13) -> 0
A14: 14 | B14: =Codestufen!C15 -> 0 | C14: =COUNTIF(V_W_Q7_Zuord,A14) -> 0 | D14: ="I33:I"&D24 -> I33:I132 | E14: =E13+1 -> 10 | F14: =HYPERLINK("#Codestufen!"&ADDRESS(E14+1,D$6),IF(INDEX(V_W_Q7_CodestufenName,E14)=0,"",INDEX(V_W_Q7_CodestufenName,E14))) | G14: =INDEX(V_W_Q7_Codestufen,E14) -> 0
A15: 15 | B15: =Codestufen!C16 -> 0 | C15: =COUNTIF(V_W_Q7_Zuord,A15) -> 0 | D15: Anzahl ohne Zuordnung | E15: =E14+1 -> 11 | F15: =HYPERLINK("#Codestufen!"&ADDRESS(E15+1,D$6),IF(INDEX(V_W_Q7_CodestufenName,E15)=0,"",INDEX(V_W_Q7_CodestufenName,E15))) | G15: =INDEX(V_W_Q7_Codestufen,E15) -> 0
A16: 16 | B16: =Codestufen!C17 -> 0 | C16: =COUNTIF(V_W_Q7_Zuord,A16) -> 0 | D16: ="J33:J"&D24 -> J33:J132 | E16: =E15+1 -> 12 | F16: =HYPERLINK("#Codestufen!"&ADDRESS(E16+1,D$6),IF(INDEX(V_W_Q7_CodestufenName,E16)=0,"",INDEX(V_W_Q7_CodestufenName,E16))) | G16: =INDEX(V_W_Q7_Codestufen,E16) -> 0
A17: 17 | B17: =Codestufen!C18 -> 0 | C17: =COUNTIF(V_W_Q7_Zuord,A17) -> 0 | D17: Anzahl Zuordnungen ohne Verbatim | E17: =E16+1 -> 13 | F17: =HYPERLINK("#Codestufen!"&ADDRESS(E17+1,D$6),IF(INDEX(V_W_Q7_CodestufenName,E17)=0,"",INDEX(V_W_Q7_CodestufenName,E17))) | G17: =INDEX(V_W_Q7_Codestufen,E17) -> 0 | H17: =IF(SUM(V_W_Q7_Codestufen)<>SUMIF(V_W_Q7_CodestufenName,"<>0",V_W_Q7_Codestufen),"Es gibt Nennungen, die keinem Code zugeordnet werden können.","")&IF(SUM(V_W_Q7_AnzZuordOVerb)>0,"Es gibt Zuordnungen bei nicht vorhandenen Verbatims.","")
A18: 18 | B18: =Codestufen!C19 -> 0 | C18: =COUNTIF(V_W_Q7_Zuord,A18) -> 0 | D18: ="K33:K"&D24 -> K33:K132 | E18: =E17+1 -> 14 | F18: =HYPERLINK("#Codestufen!"&ADDRESS(E18+1,D$6),IF(INDEX(V_W_Q7_CodestufenName,E18)=0,"",INDEX(V_W_Q7_CodestufenName,E18))) | G18: =INDEX(V_W_Q7_Codestufen,E18) -> 0
A19: 19 | B19: =Codestufen!C20 -> 0 | C19: =COUNTIF(V_W_Q7_Zuord,A19) -> 0 | D19: Codestufen Name | E19: =E18+1 -> 15 | F19: =HYPERLINK("#Codestufen!"&ADDRESS(E19+1,D$6),IF(INDEX(V_W_Q7_CodestufenName,E19)=0,"",INDEX(V_W_Q7_CodestufenName,E19))) | G19: =INDEX(V_W_Q7_Codestufen,E19) -> 0
A20: 20 | B20: =Codestufen!C21 -> 0 | C20: =COUNTIF(V_W_Q7_Zuord,A20) -> 0 | D20: B1:B100 | E20: =E19+1 -> 16 | F20: =HYPERLINK("#Codestufen!"&ADDRESS(E20+1,D$6),IF(INDEX(V_W_Q7_CodestufenName,E20)=0,"",INDEX(V_W_Q7_CodestufenName,E20))) | G20: =INDEX(V_W_Q7_Codestufen,E20) -> 0
A21: 21 | B21: =Codestufen!C22 -> 0 | C21: =COUNTIF(V_W_Q7_Zuord,A21) -> 0 | D21: Codestufen Anzahl | E21: =E20+1 -> 17 | F21: =HYPERLINK("#Codestufen!"&ADDRESS(E21+1,D$6),IF(INDEX(V_W_Q7_CodestufenName,E21)=0,"",INDEX(V_W_Q7_CodestufenName,E21))) | G21: =INDEX(V_W_Q7_Codestufen,E21) -> 0
A22: 22 | B22: =Codestufen!C23 -> 0 | C22: =COUNTIF(V_W_Q7_Zuord,A22) -> 0 | D22: C1:C100 | E22: =E21+1 -> 18 | F22: =HYPERLINK("#Codestufen!"&ADDRESS(E22+1,D$6),IF(INDEX(V_W_Q7_CodestufenName,E22)=0,"",INDEX(V_W_Q7_CodestufenName,E22))) | G22: =INDEX(V_W_Q7_Codestufen,E22) -> 0
A23: 23 | B23: =Codestufen!C24 -> 0 | C23: =COUNTIF(V_W_Q7_Zuord,A23) -> 0 | D23: Letzte Zeile | E23: =E22+1 -> 19 | F23: =HYPERLINK("#Codestufen!"&ADDRESS(E23+1,D$6),IF(INDEX(V_W_Q7_CodestufenName,E23)=0,"",INDEX(V_W_Q7_CodestufenName,E23))) | G23: =INDEX(V_W_Q7_Codestufen,E23) -> 0
A24: 24 | B24: =Codestufen!C25 -> 0 | C24: =COUNTIF(V_W_Q7_Zuord,A24) -> 0 | D24: 132 | E24: =E23+1 -> 20 | F24: =HYPERLINK("#Codestufen!"&ADDRESS(E24+1,D$6),IF(INDEX(V_W_Q7_CodestufenName,E24)=0,"",INDEX(V_W_Q7_CodestufenName,E24))) | G24: =INDEX(V_W_Q7_Codestufen,E24) -> 0
A25: 25 | B25: =Codestufen!C26 -> 0 | C25: =COUNTIF(V_W_Q7_Zuord,A25) -> 0 | F25: ="Zuordnungen > " &E24& " und < "&E26 -> Zuordnungen > 20 und < 97 | G25: =COUNTIF(V_W_Q7_Zuord,"<"&E26)-SUM(G4:G24) -> 0
A26: 26 | B26: =Codestufen!C27 -> 0 | C26: =COUNTIF(V_W_Q7_Zuord,A26) -> 0 | D26: Feste | E26: =D29 -> 97 | F26: =HYPERLINK("#Codestufen!"&ADDRESS(E26+1,D$6),IF(INDEX(V_W_Q7_CodestufenName,E26)=0,"",INDEX(V_W_Q7_CodestufenName,E26))) | G26: =INDEX(V_W_Q7_Codestufen,E26) -> 0
A27: 27 | B27: =Codestufen!C28 -> 0 | C27: =COUNTIF(V_W_Q7_Zuord,A27) -> 0 | D27: Werte | E27: =E26+1 -> 98 | F27: =HYPERLINK("#Codestufen!"&ADDRESS(E27+1,D$6),IF(INDEX(V_W_Q7_CodestufenName,E27)=0,"",INDEX(V_W_Q7_CodestufenName,E27))) | G27: =INDEX(V_W_Q7_Codestufen,E27) -> 0
A28: 28 | B28: =Codestufen!C29 -> 0 | C28: =COUNTIF(V_W_Q7_Zuord,A28) -> 0 | D28: ab | E28: =E27+1 -> 99 | F28: =HYPERLINK("#Codestufen!"&ADDRESS(E28+1,D$6),IF(INDEX(V_W_Q7_CodestufenName,E28)=0,"",INDEX(V_W_Q7_CodestufenName,E28))) | G28: =INDEX(V_W_Q7_Codestufen,E28) -> 0
A29: 29 | B29: =Codestufen!C30 -> 0 | C29: =COUNTIF(V_W_Q7_Zuord,A29) -> 0 | D29: 97 | E29: =E28+1 -> 100 | F29: =HYPERLINK("#Codestufen!"&ADDRESS(E29+1,D$6),IF(INDEX(V_W_Q7_CodestufenName,E29)=0,"",INDEX(V_W_Q7_CodestufenName,E29))) | G29: =INDEX(V_W_Q7_Codestufen,E29) -> 0
A30: 30 | B30: =Codestufen!C31 -> 0 | C30: =COUNTIF(V_W_Q7_Zuord,A30) -> 0 | F30: ="Zuordnungen > " &E29 -> Zuordnungen > 100 | G30: =COUNTIF(V_W_Q7_Zuord,">"&E29) -> 0
A31: 31 | B31: =Codestufen!C32 -> 0 | C31: =COUNTIF(V_W_Q7_Zuord,A31) -> 0
A32: 32 | B32: =Codestufen!C33 -> 0 | C32: =COUNTIF(V_W_Q7_Zuord,A32) -> 0 | D32: Orig. Variable | E32: ID | F32: Antwort | G32: Zuord 1 | H32: Verbatim? | I32: Zuordnungen? | J32: Ohne Zuordnung | K32: Zuord. ohne Verb. | L32: CalcV1 | M32: CalcV2 | N32: CalcV3 | O32: Calc1 Zuord 1 | P32: Calc2 Zuord 1 | Q32: Calc3 Zuord 1 | R32: CalcN1 | S32: CalcN2 | T32: CalcN3
A33: 33 | B33: =Codestufen!C34 -> 0 | C33: =COUNTIF(V_W_Q7_Zuord,A33) -> 0 | D33: q7 | E33: 77 | F33: bla sadness | G33: 1 | H33: =IF(TRIM(F33)="",0,1) -> 1 | I33: =COUNT(G33:G33) -> 1 | J33: =IF(I33 >= H33,0,1) -> 0 | K33: =IF(AND(I33 > 0,H33=0),1,0) -> 0
A34: 34 | B34: =Codestufen!C35 -> 0 | C34: =COUNTIF(V_W_Q7_Zuord,A34) -> 0 | D34: q7 | E34: 87 | F34: bla sadness | G34: 1 | H34: =IF(TRIM(F34)="",0,1) -> 1 | I34: =COUNT(G34:G34) -> 1 | J34: =IF(I34 >= H34,0,1) -> 0 | K34: =IF(AND(I34 > 0,H34=0),1,0) -> 0
A35: 35 | B35: =Codestufen!C36 -> 0 | C35: =COUNTIF(V_W_Q7_Zuord,A35) -> 0 | D35: q7 | E35: 6 | F35: bla pain | G35: 4 | H35: =IF(TRIM(F35)="",0,1) -> 1 | I35: =COUNT(G35:G35) -> 1 | J35: =IF(I35 >= H35,0,1) -> 0 | K35: =IF(AND(I35 > 0,H35=0),1,0) -> 0
A36: 36 | B36: =Codestufen!C37 -> 0 | C36: =COUNTIF(V_W_Q7_Zuord,A36) -> 0 | D36: q7 | E36: 15 | F36: bla pain | G36: 4 | H36: =IF(TRIM(F36)="",0,1) -> 1 | I36: =COUNT(G36:G36) -> 1 | J36: =IF(I36 >= H36,0,1) -> 0 | K36: =IF(AND(I36 > 0,H36=0),1,0) -> 0
A37: 37 | B37: =Codestufen!C38 -> 0 | C37: =COUNTIF(V_W_Q7_Zuord,A37) -> 0 | D37: q7 | E37: 23 | F37: bla pain | G37: 4 | H37: =IF(TRIM(F37)="",0,1) -> 1 | I37: =COUNT(G37:G37) -> 1 | J37: =IF(I37 >= H37,0,1) -> 0 | K37: =IF(AND(I37 > 0,H37=0),1,0) -> 0
A38: 38 | B38: =Codestufen!C39 -> 0 | C38: =COUNTIF(V_W_Q7_Zuord,A38) -> 0 | D38: q7 | E38: 27 | F38: bla pain | G38: 4 | H38: =IF(TRIM(F38)="",0,1) -> 1 | I38: =COUNT(G38:G38) -> 1 | J38: =IF(I38 >= H38,0,1) -> 0 | K38: =IF(AND(I38 > 0,H38=0),1,0) -> 0
A39: 39 | B39: =Codestufen!C40 -> 0 | C39: =COUNTIF(V_W_Q7_Zuord,A39) -> 0 | D39: q7 | E39: 44 | F39: bla pain | G39: 4 | H39: =IF(TRIM(F39)="",0,1) -> 1 | I39: =COUNT(G39:G39) -> 1 | J39: =IF(I39 >= H39,0,1) -> 0 | K39: =IF(AND(I39 > 0,H39=0),1,0) -> 0
A40: 40 | B40: =Codestufen!C41 -> 0 | C40: =COUNTIF(V_W_Q7_Zuord,A40) -> 0 | D40: q7 | E40: 45 | F40: bla pain | G40: 4 | H40: =IF(TRIM(F40)="",0,1) -> 1 | I40: =COUNT(G40:G40) -> 1 | J40: =IF(I40 >= H40,0,1) -> 0 | K40: =IF(AND(I40 > 0,H40=0),1,0) -> 0
...
